Workbook

Sheet Caliber
A1: Pistol ammo | B1: Name | C1: Power | D1: ToArmorPre | E1: Random type | F1: Damage type | G1: . | H1: .. | I1: Notes:
B2: Taser | C2: 40 | D2: 0 | E2: 6 | F2: 6 | I2: Stuns
B3: 38 Special | C3: 26 | D3: 0 | E3: 6 | F3: 1
B4: 9mm Makarov | C4: 29 | D4: 0 | E4: 6 | F4: 1
B5: 9mm Pistol | C5: 31 | D5: 0 | E5: 6 | F5: 1
B6: 9mm gyurza | C6: 34 | D6: 0.4 | E6: 6 | F6: 1
B7: 5.7mm | C7: 33 | D7: 0.4 | E7: 6 | F7: 1
B8: HK 4.6x30mm | C8: 32 | D8: 0.3 | E8: 6 | F8: 1
B9: 45 ACP | C9: 35 | D9: 0.1 | E9: 6 | F9: 1
B10: 50 AE | C10: 40 | D10: 0 | E10: 6 | F10: 1 | I10: 1.25 to health, 1.5 armor effectiveness. More effecive against targets without armor, less effective against targest with armor. (Graph in Other Info)
B11: 6.5mm CBJ | C11: 30 | D11: 0.35 | E11: 6 | F11: 1 | M11: 4.73 Caseless | N11: 35 | O11: 0.3 | P11: 6 | Q11: 1
A12: Rifle ammo | B12: Name | C12: Power | D12: ToArmorPre | E12: Random type | F12: Damage type | G12: . | H12: .. | I12: Notes: | M12: 5.45mm | N12: 36 | O12: 0.3 | P12: 6 | Q12: 1
B13: 4.73 Caseless | C13: 35 | D13: 0.3 | E13: 6 | F13: 1 | M13: 5.56mm NATO | N13: 37 | O13: 0.4 | P13: 6 | Q13: 1
B14: 5.45mm | C14: 36 | D14: 0.3 | E14: 6 | F14: 1 | M14: 22 Long Rifle | N14: 33 | O14: 0 | P14: 6 | Q14: 1
B15: 5.56mm | C15: 37 | D15: 0.4 | E15: 6 | F15: 1 | M15: 7.62mm Soviet | N15: 43 | O15: 0.6 | P15: 6 | Q15: 1
B16: 22 Long Rifle | C16: 28 | D16: 0 | E16: 6 | F16: 1 | M16: 7.62mm NATO | N16: 45 | O16: 0.6 | P16: 6 | Q16: 1
B17: 7.62mm Soviet | C17: 43 | D17: 0.6 | E17: 6 | F17: 1 | M17: 7.62mm Soviet MMR | N17: 49 | O17: 0.7 | P17: 6 | Q17: 1
B18: 7.62mm NATO | C18: 45 | D18: 0.6 | E18: 6 | F18: 1 | M18: 9.39mm | N18: 51 | O18: 0.7 | P18: 6 | Q18: 1
B19: 7.62mm Soviet MMR | C19: 49 | D19: 0.7 | E19: 6 | F19: 1 | M19: .338 Lapua | N19: 61 | O19: 0.8 | P19: 6 | Q19: 1
B20: 9.39mm | C20: 51 | D20: 0.7 | E20: 6 | F20: 1 | M20: .50 BMG | N20: 70 | O20: 1 | P20: 6 | Q20: 1
B21: .338 Lapua | C21: 61 | D21: 0.8 | E21: 6 | F21: 1 | M21: 12.7mm | N21: 75 | O21: 1 | P21: 6 | Q21: 1
B22: .50 BMG | C22: 70 | D22: 1 | E22: 6 | F22: 1
B23: 12.7mm | C23: 75 | D23: 1 | E23: 6 | F23: 1 | M23: 12G Buckshot | N23: 25 | O23: 10 | P23: 100 | Q23: 0 | R23: 1 | S23: 1
B24: .30-06 | C24: 40 | D24: 0.5 | E24: 6 | F24: 1 | M24: 12G Slug | N24: 45 | O24: 1 | P24: n/a | Q24: 0.7 | R24: 6 | S24: 1
A25: Shotgun ammo | B25: Name | C25: Power | D25: Pellets | E25: SG Spread | F25: ToArmorPre | G25: Random type | H25: Damage type | I25: Notes: | M25: 12G Non-lethal | N25: 10 | O25: 10 | P25: 100 | Q25: 0 | R25: 1 | S25: 1
B26: 12G Buckshot | C26: 18 | D26: 10 | E26: 0 | F26: 0 | G26: 1 | H26: 1 | M26: Shrapnel-25 (4G) | N26: 25 | O26: 20 | P26: 100 | Q26: 0 | R26: 1 | S26: 1
B27: 12G Slug | C27: 45 | D27: 1 | E27: n/a | F27: 0.7 | G27: 6 | H27: 1 | M27: Barricade slug (4G) | N27: 55 | O27: 1 | P27: n/a | Q27: 1 | R27: 6 | S27: 1
B28: 12G Non-lethal | C28: 10 | D28: 10 | E28: 0 | F28: 0 | G28: 1 | H28: 10 | I28: Cant wound, power reduces over range. | M28: Volna-R Non-lethal (4G) | N28: 10 | O28: 20 | P28: 100 | Q28: 0 | R28: 1 | S28: 1
B29: 12G Incendiary | C29: 18 | D29: 10 | E29: 0 | F29: 0 | G29: 1 | H29: 2 | I29: Sets things on fire
B30: 12G Breaching | C30: 10 | D30: 4 | E30: 25 | F30: 0 | G30: 1 | H30: 11 | I30: 3x ToTile Damage | M30: 40MM Frag | N30: 50 | O30: 0.2 | P30: 3 | Q30: 1 | R30: 3
B31: Shrapnel-25 (4G) | C31: 18 | D31: 20 | E31: 0 | F31: 0 | G31: 1 | H31: 1 | M31: 40MM Smoke | N31: 40 | O31: 0 | P31: 5 | Q31: 1 | R31: 9
B32: Barricade slug (4G) | C32: 55 | D32: 1 | E32: n/a | F32: 1 | G32: 6 | H32: 1 | M32: 40MM Non-lethal | N32: 40 | O32: 0 | P32: 0 | Q32: 6 | R32: 1
B33: Volna-R Non-lethal (4G) | C33: 10 | D33: 20 | E33: 0 | F33: 0 | G33: 1 | H33: 10 | I33: Cant wound, power reduces over range. | M33: APAV40 | N33: 60 | O33: 0 | P33: 3 | Q33: 1 | R33: 1
A34: Explosive | B34: Name | C34: Power | D34: ToArmorPre | E34: Radius | F34: RandomType | G34: DamageType | H34: . | I34: Notes: | M34: Carl Gustaf HEAT | N34: 200 | O34: 1 | P34: 3 | Q34: 1 | R34: 3
B35: 40MM Frag | C35: 50 | D35: 0.2 | E35: 3 | F35: 1 | G35: 3 | I35: Arcing. | M35: Carl Gustaf HE | N35: 100 | O35: 0.5 | P35: 6 | Q35: 1 | R35: 3
B36: 40MM Smoke | C36: 40 | D36: 0 | E36: 5 | F36: 1 | G36: 9 | I36: Arcing + Smoke. | M36: RPG HEAT | N36: 150 | O36: 1 | P36: 3 | Q36: 1 | R36: 3
B37: 40MM Non-lethal | C37: 40 | D37: 0 | E37: 0 | F37: 6 | G37: 10 | I37: Arcing, Cant wound, power reduces over range. | M37: RPG 29 HEAT | N37: 190 | O37: 1 | P37: 3 | Q37: 1 | R37: 3
B38: APAV40 | C38: 60 | D38: 0 | E38: 3 | F38: 1 | G38: 1 | I38: Arcing, No armor damage at all. | M38: RPG Thermobaric | N38: 140 | O38: 0.2 | P38: 7 | Q38: 1 | R38: 3
B39: Carl Gustaf HEAT | C39: 200 | D39: 1 | E39: 3 | F39: 1 | G39: 3
B40: Carl Gustaf HE | C40: 100 | D40: 0.5 | E40: 6 | F40: 1 | G40: 3
...

Sheet Pistols
A1: Name | B1: weight | C1: size | D1: Cost | E1: two handed | F1: One hand pen. | G1: kneel bouns | H1: tuAimed | I1: tuSnap | J1: tuAuto | K1: accAimed | L1: accSnap | M1: accAuto | N1: rangeAimed | O1: rangeSnap | P1: rangeAuto | Q1: maxRange | R1: minRange | S1: Aimed shots | T1: snap shots | U1: auto shots | V1: Caliber | W1: Power | X1: toArmorPre | Y1: Mag sizes | Z1: Notes:
A2: M1911 | B2: 12 | C2: 1x2 | D2: 3700 | E2: FALSE | F2: 100 | G2: 100 | H2: 60 | I2: 30 | J2: N/A | K2: 70 | L2: 40 | M2: N/A | N2: 12 | O2: 8 | P2: N/A | Q2: 25 | R2: 0 | S2: 1 | T2: 2 | U2: N/A | V2: 45 ACP | W2: =INDEX(Caliber!B2:'Caliber'!C9,MATCH(V2,Caliber!B2:'Caliber'!B9,0),2) -> 35 | X2: =INDEX(Caliber!C2:'Caliber'!D9,MATCH(V2,Caliber!B2:'Caliber'!B9,0),2) -> 0.1 | Y2: [7]
A3: Desert Eagle | B3: 16 | C3: 1x2 | D3: 20000 | E3: FALSE | F3: 100 | G3: 100 | H3: 60 | I3: 30 | J3: N/A | K3: 85 | L3: 45 | M3: N/A | N3: 12 | O3: 8 | P3: N/A | Q3: 25 | R3: 0 | S3: 1 | T3: 2 | U3: N/A | V3: 50 AE | W3: {=INDEX(Caliber!B2:'Caliber'!C10,MATCH(INDIRECT(ADDRESS(ROW(),COLUMN()-1)),Caliber!B2:'Caliber'!B10,0),2)} -> 40 | X3: {=INDEX(Caliber!C2:'Caliber'!D10,MATCH(INDIRECT(ADDRESS(ROW(),COLUMN()-2)),Caliber!B2:'Caliber'!B10,0),2)} -> 0 | Y3: [7] | Z3: More hp damage, less effective vs armor
A4: Manhurin | B4: 7 | C4: 1x1 | D4: 6000 | E4: FALSE | F4: 100 | G4: 100 | H4: 50 | I4: 20 | J4: N/A | K4: 70 | L4: 45 | M4: N/A | N4: 8 | O4: 6 | P4: N/A | Q4: 16 | R4: 0 | S4: 1 | T4: 2 | U4: N/A | V4: 38 Special | W4: =INDEX(Caliber!B2:'Caliber'!C9,MATCH(V4,Caliber!B2:'Caliber'!B9,0),2) -> 26 | X4: =INDEX(Caliber!C2:'Caliber'!D9,MATCH(V4,Caliber!B2:'Caliber'!B9,0),2) -> 0 | Y4: [6]
A5: Taser | B5: 12 | C5: 1x2 | D5: 10000 | E5: FALSE | F5: 100 | G5: 100 | H5: 50 | I5: 25 | J5: N/A | K5: 100 | L5: 50 | M5: N/A | N5: 6 | O5: 6 | P5: N/A | Q5: 6 | R5: 0 | S5: 1 | T5: 1 | U5: N/A | V5: Taser | W5: =INDEX(Caliber!B2:'Caliber'!C9,MATCH(V5,Caliber!B2:'Caliber'!B9,0),2) -> 40 | X5: =INDEX(Caliber!C2:'Caliber'!D9,MATCH(V5,Caliber!B2:'Caliber'!B9,0),2) -> 0 | Y5: [1] | Z5: Stuns
A6: Vektor | B6: 11 | C6: 1x2 | D6: 12000 | E6: FALSE | F6: 100 | G6: 100 | H6: 50 | I6: 21 | J6: N/A | K6: 60 | L6: 40 | M6: N/A | N6: 12 | O6: 10 | P6: N/A | Q6: 22 | R6: 0 | S6: 1 | T6: 2 | U6: N/A | V6: 9mm gyurza | W6: =INDEX(Caliber!B2:'Caliber'!C9,MATCH(V6,Caliber!B2:'Caliber'!B9,0),2) -> 34 | X6: =INDEX(Caliber!C2:'Caliber'!D9,MATCH(V6,Caliber!B2:'Caliber'!B9,0),2) -> 0.4 | Y6: [20]
A7: Five Seven | B7: 6 | C7: 1x2 | D7: 12500 | E7: FALSE | F7: 100 | G7: 100 | H7: 50 | I7: 21 | J7: N/A | K7: 65 | L7: 42 | M7: N/A | N7: 11 | O7: 8 | P7: N/A | Q7: 22 | R7: 0 | S7: 1 | T7: 2 | U7: N/A | V7: 5.7mm | W7: =INDEX(Caliber!B2:'Caliber'!C9,MATCH(V7,Caliber!B2:'Caliber'!B9,0),2) -> 33 | X7: =INDEX(Caliber!C2:'Caliber'!D9,MATCH(V7,Caliber!B2:'Caliber'!B9,0),2) -> 0.4 | Y7: [20]
A8: MK23 | B8: 14 | C8: 1x2 | D8: 13000 | E8: FALSE | F8: 100 | G8: 100 | H8: 50 | I8: 20 | J8: N/A | K8: 80 | L8: 50 | M8: N/A | N8: 15 | O8: 10 | P8: N/A | Q8: 25 | R8: 0 | S8: 1 | T8: 2 | U8: N/A | V8: 45 ACP | W8: =INDEX(Caliber!B2:'Caliber'!C9,MATCH(V8,Caliber!B2:'Caliber'!B9,0),2) -> 35 | X8: =INDEX(Caliber!C2:'Caliber'!D9,MATCH(V8,Caliber!B2:'Caliber'!B9,0),2) -> 0.1 | Y8: [12]
A9: Makarov | B9: 7 | C9: 1x2 | D9: N/A | E9: FALSE | F9: 100 | G9: 100 | H9: 50 | I9: 20 | J9: N/A | K9: 55 | L9: 45 | M9: N/A | N9: 10 | O9: 7 | P9: N/A | Q9: 18 | R9: 0 | S9: 1 | T9: 2 | U9: N/A | V9: 9mm Makarov | W9: =INDEX(Caliber!B2:'Caliber'!C9,MATCH(V9,Caliber!B2:'Caliber'!B9,0),2) -> 29 | X9: =INDEX(Caliber!C2:'Caliber'!D9,MATCH(V9,Caliber!B2:'Caliber'!B9,0),2) -> 0 | Y9: [10]
A10: Glock 18 (stock) | B10: 12 | C10: 1x3 | D10: N/A | E10: FALSE | F10: 100 | G10: 100 | H10: 50 | I10: 20 | J10: 40 | K10: 45 | L10: 45 | M10: 40 | N10: 8 | O10: 10 | P10: 6 | Q10: 22 | R10: 0 | S10: 3 | T10: 1 | U10: 5 | V10: 9mm Pistol | W10: =INDEX(Caliber!B2:'Caliber'!C9,MATCH(V10,Caliber!B2:'Caliber'!B9,0),2) -> 31 | X10: =INDEX(Caliber!C2:'Caliber'!D9,MATCH(V10,Caliber!B2:'Caliber'!B9,0),2) -> 0 | Y10: [10,20,30]
A11: P226 | B11: 10 | C11: 1x2 | D11: 10000 | E11: FALSE | F11: 100 | G11: 100 | H11: 45 | I11: 21 | J11: N/A | K11: 60 | L11: 40 | M11: N/A | N11: 10 | O11: 7 | P11: N/A | Q11: 20 | R11: 0 | S11: 1 | T11: 2 | U11: N/A | V11: 9mm Pistol | W11: =INDEX(Caliber!B2:'Caliber'!C9,MATCH(V11,Caliber!B2:'Caliber'!B9,0),2) -> 31 | X11: =INDEX(Caliber!C2:'Caliber'!D9,MATCH(V11,Caliber!B2:'Caliber'!B9,0),2) -> 0 | Y11: [10,20]
A12: Glock 18 | B12: 11 | C12: 1x2 | D12: 12000 | E12: FALSE | F12: 100 | G12: 100 | H12: 45 | I12: 15 | J12: 40 | K12: 38 | L12: 38 | M12: 25 | N12: 6 | O12: 8 | P12: 4 | Q12: 20 | R12: 0 | S12: 3 | T12: 1 | U12: 5 | V12: 9mm Pistol | W12: =INDEX(Caliber!B2:'Caliber'!C9,MATCH(V12,Caliber!B2:'Caliber'!B9,0),2) -> 31 | X12: =INDEX(Caliber!C2:'Caliber'!D9,MATCH(V12,Caliber!B2:'Caliber'!B9,0),2) -> 0 | Y12: [10,20,30]
A13: Stetckin | B13: 14 | C13: 1x2 | D13: 12500 | E13: FALSE | F13: 100 | G13: 100 | H13: 45 | I13: 15 | J13: 40 | K13: 35 | L13: 35 | M13: 20 | N13: 5 | O13: 8 | P13: 4 | Q13: 18 | R13: 0 | S13: 3 | T13: 1 | U13: 5 | V13: 9mm Makarov | W13: =INDEX(Caliber!B2:'Caliber'!C9,MATCH(V13,Caliber!B2:'Caliber'!B9,0),2) -> 29 | X13: =INDEX(Caliber!C2:'Caliber'!D9,MATCH(V13,Caliber!B2:'Caliber'!B9,0),2) -> 0 | Y13: [20]
A14: Glock 17 | B14: 11 | C14: 1x2 | D14: 8000 | E14: FALSE | F14: 100 | G14: 100 | H14: 40 | I14: 20 | J14: N/A | K14: 55 | L14: 35 | M14: N/A | N14: 10 | O14: 7 | P14: N/A | Q14: 20 | R14: 0 | S14: 1 | T14: 2 | U14: N/A | V14: 9mm Pistol | W14: =INDEX(Caliber!B2:'Caliber'!C9,MATCH(V14,Caliber!B2:'Caliber'!B9,0),2) -> 31 | X14: =INDEX(Caliber!C2:'Caliber'!D9,MATCH(V14,Caliber!B2:'Caliber'!B9,0),2) -> 0 | Y14: [10,20,30]
A15: M9 | B15: 8 | C15: 1x2 | D15: N/A | E15: FALSE | F15: 100 | G15: 100 | H15: 30 | I15: 15 | J15: N/A | K15: 35 | L15: 20 | M15: N/A | N15: 8 | O15: 6 | P15: N/A | Q15: 20 | R15: 0 | S15: 1 | T15: 2 | U15: N/A | V15: 9mm Pistol | W15: =INDEX(Caliber!B2:'Caliber'!C9,MATCH(V15,Caliber!B2:'Caliber'!B9,0),2) -> 31 | X15: =INDEX(Caliber!C2:'Caliber'!D9,MATCH(V15,Caliber!B2:'Caliber'!B9,0),2) -> 0 | Y15: [10,20]
A16: Browning HP | B16: 12 | C16: 1x2 | D16: N/A | E16: FALSE | F16: 100 | G16: 100 | H16: 55 | I16: 25 | J16: N/A | K16: 60 | L16: 45 | M16: N/A | N16: 10 | O16: 7 | P16: N/A | Q16: 19 | R16: 0 | S16: 1 | T16: 2 | U16: N/A | V16: 9mm Pistol | W16: =INDEX(Caliber!B3:'Caliber'!C10,MATCH(V16,Caliber!B3:'Caliber'!B10,0),2) -> 31 | X16: =INDEX(Caliber!C3:'Caliber'!D10,MATCH(V16,Caliber!B3:'Caliber'!B10,0),2) -> 0 | Y16: [10]

Sheet SMGs
A1: Name | B1: weight | C1: size | D1: Cost | E1: two handed | F1: One hand pen. | G1: kneel bouns | H1: tuAimed | I1: tuSnap | J1: tuAuto | K1: accAimed | L1: accSnap | M1: accAuto | N1: rangeAimed | O1: rangeSnap | P1: rangeAuto | Q1: maxRange | R1: minRange | S1: Aimed shots | T1: snap shots | U1: auto shots | V1: Caliber | W1: Power | X1: toArmorPre | Y1: Mag sizes | Z1: Notes:
A2: MPX | B2: 22 | C2: 1x2 | D2: 25000 | E2: FALSE | F2: 100 | G2: 115 | H2: 20 | I2: 15 | J2: 30 | K2: 55 | L2: 70 | M2: 50 | N2: 6 | O2: 8 | P2: 4 | Q2: 30 | R2: 0 | S2: 3 | T2: 1 | U2: 7 | V2: 9mm Pistol | W2: =INDEX(Caliber!B2:'Caliber'!C9,MATCH(V2,Caliber!B2:'Caliber'!B9,0),2) -> 31 | X2: =INDEX(Caliber!C2:'Caliber'!D9,MATCH(V2,Caliber!B2:'Caliber'!B9,0),2) -> 0 | Y2: [10,20,30]
A3: FMG 9 | B3: 18 | C3: 1x2 | D3: 18000 | E3: FALSE | F3: 100 | G3: 115 | H3: 30 | I3: 20 | J3: 35 | K3: 55 | L3: 60 | M3: 45 | N3: 6 | O3: 8 | P3: 4 | Q3: 30 | R3: 0 | S3: 3 | T3: 1 | U3: 7 | V3: 9mm Pistol | W3: =INDEX(Caliber!B2:'Caliber'!C9,MATCH(V3,Caliber!B2:'Caliber'!B9,0),2) -> 31 | X3: =INDEX(Caliber!C2:'Caliber'!D9,MATCH(V3,Caliber!B2:'Caliber'!B9,0),2) -> 0 | Y3: [20,30]
A4: MP7 | B4: 21 | C4: 1x2 | D4: 17500 | E4: FALSE | F4: 100 | G4: 115 | H4: 35 | I4: 20 | J4: 35 | K4: 50 | L4: 70 | M4: 55 | N4: 7 | O4: 11 | P4: 6 | Q4: 30 | R4: 0 | S4: 3 | T4: 1 | U4: 7 | V4: HK 4.6x30mm | W4: =INDEX(Caliber!B2:'Caliber'!C9,MATCH(V4,Caliber!B2:'Caliber'!B9,0),2) -> 32 | X4: =INDEX(Caliber!C2:'Caliber'!D9,MATCH(V4,Caliber!B2:'Caliber'!B9,0),2) -> 0.3 | Y4: [20,30,40]
A5: P90 | B5: 21 | C5: 1x3 | D5: 18000 | E5: TRUE | F5: 80 | G5: 115 | H5: 30 | I5: 25 | J5: 40 | K5: 55 | L5: 60 | M5: 45 | N5: 8 | O5: 10 | P5: 4 | Q5: 35 | R5: 0 | S5: 3 | T5: 1 | U5: 7 | V5: 5.7mm | W5: =INDEX(Caliber!B2:'Caliber'!C9,MATCH(V5,Caliber!B2:'Caliber'!B9,0),2) -> 33 | X5: =INDEX(Caliber!C2:'Caliber'!D9,MATCH(V5,Caliber!B2:'Caliber'!B9,0),2) -> 0.4 | Y5: [50]
A6: P90 (Sopmod) | B6: 23 | C6: 1x3 | D6: N/A | E6: TRUE | F6: 80 | G6: 115 | H6: 40 | I6: 22 | J6: 37 | K6: 70 | L6: 60 | M6: 45 | N6: 13 | O6: 20 | P6: 9 | Q6: 30 | R6: 0 | S6: 3 | T6: 1 | U6: 7 | V6: 5.7mm | W6: {=INDEX(Caliber!B2:'Caliber'!C11,MATCH(INDIRECT(ADDRESS(ROW(),COLUMN()-1)),Caliber!B2:'Caliber'!B11,0),2)} -> 33 | X6: {=INDEX(Caliber!C2:'Caliber'!D11,MATCH(INDIRECT(ADDRESS(ROW(),COLUMN()-2)),Caliber!B2:'Caliber'!B11,0),2)} -> 0.4 | Y6: [50]
A7: Vityaz | B7: 23 | C7: 1x3 | D7: 17000 | E7: TRUE | F7: 80 | G7: 115 | H7: 25 | I7: 15 | J7: 35 | K7: 55 | L7: 75 | M7: 40 | N7: 9 | O7: 11 | P7: 6 | Q7: 35 | R7: 0 | S7: 3 | T7: 1 | U7: 7 | V7: 9mm Pistol | W7: =INDEX(Caliber!B2:'Caliber'!C9,MATCH(V7,Caliber!B2:'Caliber'!B9,0),2) -> 31 | X7: =INDEX(Caliber!C2:'Caliber'!D9,MATCH(V7,Caliber!B2:'Caliber'!B9,0),2) -> 0 | Y7: [30]
A8: MP5SD | B8: 20 | C8: 1x3 | D8: 15000 | E8: TRUE | F8: 80 | G8: 115 | H8: 25 | I8: 20 | J8: 35 | K8: 50 | L8: 70 | M8: 40 | N8: 10 | O8: 12 | P8: 6 | Q8: 30 | R8: 0 | S8: 3 | T8: 1 | U8: 7 | V8: 9mm Pistol | W8: =INDEX(Caliber!B2:'Caliber'!C9,MATCH(V8,Caliber!B2:'Caliber'!B9,0),2) -> 31 | X8: =INDEX(Caliber!C2:'Caliber'!D9,MATCH(V8,Caliber!B2:'Caliber'!B9,0),2) -> 0 | Y8: [10,20,30,40]
A9: CBJ-MS | B9: 21 | C9: 1x2 | D9: 20000 | E9: TRUE | F9: 80 | G9: 115 | H9: 25 | I9: 20 | J9: 45 | K9: 49 | L9: 70 | M9: 40 | N9: 11 | O9: 13 | P9: 8 | Q9: 30 | R9: 0 | S9: 3 | T9: 1 | U9: 7 | V9: 6.5mm CBJ | W9: {=INDEX(Caliber!B2:'Caliber'!C11,MATCH(INDIRECT(ADDRESS(ROW(),COLUMN()-1)),Caliber!B2:'Caliber'!B11,0),2)} -> 30 | X9: {=INDEX(Caliber!C2:'Caliber'!D11,MATCH(INDIRECT(ADDRESS(ROW(),COLUMN()-2)),Caliber!B2:'Caliber'!B11,0),2)} -> 0.35 | Y9: [30,100]
A10: Versek | B10: 15 | C10: 1x2 | D10: 23000 | E10: FALSE | F10: 100 | G10: 115 | H10: 30 | I10: 25 | J10: 35 | K10: 45 | L10: 60 | M10: 40 | N10: 4 | O10: 6 | P10: 0 | Q10: 25 | R10: 0 | S10: 3 | T10: 1 | U10: 7 | V10: 9mm gyurza | W10: =INDEX(Caliber!B2:'Caliber'!C9,MATCH(V10,Caliber!B2:'Caliber'!B9,0),2) -> 34 | X10: =INDEX(Caliber!C2:'Caliber'!D9,MATCH(V10,Caliber!B2:'Caliber'!B9,0),2) -> 0.4 | Y10: [20,30]
A11: Uzi | B11: 28 | C11: 1x2 | D11: 14000 | E11: FALSE | F11: 100 | G11: 115 | H11: 25 | I11: 20 | J11: 30 | K11: 45 | L11: 55 | M11: 40 | N11: 6 | O11: 10 | P11: 4 | Q11: 20 | R11: 0 | S11: 3 | T11: 1 | U11: 7 | V11: 9mm Pistol | W11: =INDEX(Caliber!B2:'Caliber'!C9,MATCH(V11,Caliber!B2:'Caliber'!B9,0),2) -> 31 | X11: =INDEX(Caliber!C2:'Caliber'!D9,MATCH(V11,Caliber!B2:'Caliber'!B9,0),2) -> 0 | Y11: [20,30,40]
A12: Skorpion | B12: 14 | C12: 1x2 | D12: N/A | E12: FALSE | F12: 100 | G12: 115 | H12: 35 | I12: 30 | J12: 40 | K12: 50 | L12: 60 | M12: 35 | N12: 7 | O12: 10 | P12: 4 | Q12: 20 | R12: 0 | S12: 3 | T12: 1 | U12: 7 | V12: 9mm Makarov | W12: =INDEX(Caliber!B2:'Caliber'!C9,MATCH(V12,Caliber!B2:'Caliber'!B9,0),2) -> 29 | X12: =INDEX(Caliber!C2:'Caliber'!D9,MATCH(V12,Caliber!B2:'Caliber'!B9,0),2) -> 0 | Y12: [10,20,30]
A13: UMP | B13: 20 | C13: 1x3 | D13: 19000 | E13: TRUE | F13: 80 | G13: 115 | H13: 25 | I13: 20 | J13: 40 | K13: 50 | L13: 80 | M13: 30 | N13: 12 | O13: 14 | P13: 8 | Q13: 40 | R13: 0 | S13: 3 | T13: 1 | U13: 7 | V13: 45 ACP | W13: =INDEX(Caliber!B2:'Caliber'!C9,MATCH(V13,Caliber!B2:'Caliber'!B9,0),2) -> 35 | X13: =INDEX(Caliber!C2:'Caliber'!D9,MATCH(V13,Caliber!B2:'Caliber'!B9,0),2) -> 0.1 | Y13: [25]
A14: Tec 9 | B14: 13 | C14: 1x2 | D14: N/A | E14: TRUE | F14: 80 | G14: 115 | H14: 30 | I14: 25 | J14: 35 | K14: 45 | L14: 60 | M14: 30 | N14: 7 | O14: 10 | P14: 4 | Q14: 20 | R14: 0 | S14: 3 | T14: 1 | U14: 7 | V14: 9mm Pistol | W14: =INDEX(Caliber!B2:'Caliber'!C9,MATCH(V14,Caliber!B2:'Caliber'!B9,0),2) -> 31 | X14: =INDEX(Caliber!C2:'Caliber'!D9,MATCH(V14,Caliber!B2:'Caliber'!B9,0),2) -> 0 | Y14: [10,20,30,40]
A15: Skorpion Evo | B15: 22 | C15: 1x3 | D15: 25000 | E15: TRUE | F15: 80 | G15: 115 | H15: 20 | I15: 15 | J15: 25 | K15: 30 | L15: 50 | M15: 30 | N15: 8 | O15: 10 | P15: 3 | Q15: 20 | R15: 0 | S15: 5 | T15: 1 | U15: 10 | V15: 9mm Pistol | W15: =INDEX(Caliber!B2:'Caliber'!C9,MATCH(V15,Caliber!B2:'Caliber'!B9,0),2) -> 31 | X15: =INDEX(Caliber!C2:'Caliber'!D9,MATCH(V15,Caliber!B2:'Caliber'!B9,0),2) -> 0 | Y15: [30,40]
A16: M3 Grease Gun | B16: 19 | C16: 1x3 | D16: N/A | E16: TRUE | F16: 80 | G16: 115 | H16: 40 | I16: 35 | J16: 45 | K16: 55 | L16: 65 | M16: 35 | N16: 9 | O16: 11 | P16: 7 | Q16: 30 | R16: 0 | S16: 3 | T16: 1 | U16: 6 | V16: 45 ACP | W16: =INDEX(Caliber!B2:'Caliber'!C9,MATCH(V16,Caliber!B2:'Caliber'!B9,0),2) -> 35 | X16: =INDEX(Caliber!C2:'Caliber'!D9,MATCH(V16,Caliber!B2:'Caliber'!B9,0),2) -> 0.1 | Y16: [25]
A17: Kriss Vector | B17: 26 | C17: 1x3 | D17: N/A | E17: TRUE | F17: 80 | G17: 115 | H17: 25 | I17: 15 | J17: 25 | K17: 30 | L17: 40 | M17: 20 | N17: 6 | O17: 9 | P17: 4 | Q17: 20 | R17: 0 | S17: 5 | T17: 1 | U17: 10 | V17: 45 ACP | W17: =INDEX(Caliber!B2:'Caliber'!C9,MATCH(V16,Caliber!B2:'Caliber'!B9,0),2) -> 35 | X17: =INDEX(Caliber!C2:'Caliber'!D9,MATCH(V16,Caliber!B2:'Caliber'!B9,0),2) -> 0.1 | Y17: [25]

Sheet Rifles
A1: Name | B1: weight | C1: size | D1: Cost | E1: GL/UBS firemode | F1: two handed | G1: One hand pen. | H1: kneel bouns | I1: tuAimed | J1: tuSnap | K1: tuAuto | L1: accAimed | M1: accSnap | N1: accAuto | O1: rangeAimed | P1: rangeSnap | Q1: rangeAuto | R1: maxRange | S1: minRange | T1: Aimed shots | U1: snap shots | V1: auto shots | W1: Caliber | X1: Power | Y1: toArmorPre | Z1: Mag sizes | AA1: Notes:
A2: AK 74 | B2: 23 | C2: 1x3 | D2: N/A | E2: N/A | F2: TRUE | G2: 50 | H2: 125 | I2: 55 | J2: 45 | K2: 60 | L2: 50 | M2: 60 | N2: 35 | O2: 24 | P2: 34 | Q2: 10 | R2: 200 | S2: 0 | T2: 3 | U2: 1 | V2: 5 | W2: 5.45mm | X2: {=INDEX(Caliber!B13:'Caliber'!C23,MATCH(INDIRECT(ADDRESS(ROW(),COLUMN()-1)),Caliber!B13:'Caliber'!B23,0),2)} -> 36 | Y2: {=INDEX(Caliber!C13:'Caliber'!D23,MATCH(INDIRECT(ADDRESS(ROW(),COLUMN()-2)),Caliber!B13:'Caliber'!B23,0),2)} -> 0.3 | Z2: [30,45,60]
A3: AK12 | B3: 20 | C3: 1x3 | D3: 28000 | E3: N/A | F3: TRUE | G3: 50 | H3: 125 | I3: 55 | J3: 45 | K3: 60 | L3: 60 | M3: 70 | N3: 45 | O3: 25 | P3: 35 | Q3: 11 | R3: 200 | S3: 0 | T3: 3 | U3: 1 | V3: 5 | W3: 5.45mm | X3: =INDEX(Caliber!B13:'Caliber'!C23,MATCH(W3,Caliber!B13:'Caliber'!B23,0),2) -> 36 | Y3: =INDEX(Caliber!C13:'Caliber'!D23,MATCH(W3,Caliber!B13:'Caliber'!B23,0),2) -> 0.3 | Z3: [30,45,60]
A4: AK12 (Scoped) | B4: 22 | C4: 1x3 | D4: N/A | E4: N/A | F4: TRUE | G4: 50 | H4: 125 | I4: 70 | J4: 45 | K4: 60 | L4: 80 | M4: 65 | N4: 35 | O4: 30 | P4: 40 | Q4: 11 | R4: 200 | S4: 0 | T4: 3 | U4: 1 | V4: 5 | W4: 5.45mm | X4: =INDEX(Caliber!B13:'Caliber'!C23,MATCH(W4,Caliber!B13:'Caliber'!B23,0),2) -> 36 | Y4: =INDEX(Caliber!C13:'Caliber'!D23,MATCH(W4,Caliber!B13:'Caliber'!B23,0),2) -> 0.3 | Z4: [30,45,60]
A5: AK15 | B5: 22 | C5: 1x3 | D5: 31000 | E5: N/A | F5: TRUE | G5: 50 | H5: 125 | I5: 55 | J5: 45 | K5: 60 | L5: 65 | M5: 70 | N5: 40 | O5: 33 | P5: 43 | Q5: 10 | R5: 200 | S5: 0 | T5: 3 | U5: 1 | V5: 5 | W5: 7.62mm Soviet | X5: =INDEX(Caliber!B13:'Caliber'!C23,MATCH(W5,Caliber!B13:'Caliber'!B23,0),2) -> 43 | Y5: =INDEX(Caliber!C13:'Caliber'!D23,MATCH(W5,Caliber!B13:'Caliber'!B23,0),2) -> 0.6 | Z5: [30,40,75]
A6: AK15 (Scoped) | B6: 24 | C6: 1x3 | D6: N/A | E6: N/A | F6: TRUE | G6: 50 | H6: 125 | I6: 70 | J6: 45 | K6: 60 | L6: 85 | M6: 65 | N6: 30 | O6: 38 | P6: 48 | Q6: 10 | R6: 200 | S6: 0 | T6: 3 | U6: 1 | V6: 5 | W6: 7.62mm Soviet | X6: =INDEX(Caliber!B13:'Caliber'!C23,MATCH(W6,Caliber!B13:'Caliber'!B23,0),2) -> 43 | Y6: =INDEX(Caliber!C13:'Caliber'!D23,MATCH(W6,Caliber!B13:'Caliber'!B23,0),2) -> 0.6 | Z6: [30,40,75]
A7: AK-74 (GP-25) | B7: 31 | C7: 1x3 | D7: N/A | E7: Snap | F7: TRUE | G7: 50 | H7: 125 | I7: 55 | J7: 70 | K7: 60 | L7: 50 | M7: 35 | N7: 35 | O7: 24 | P7: 16 | Q7: 10 | R7: 200 | S7: 0 | T7: 3 | U7: 1 | V7: 5 | W7: 5.45mm | X7: {=INDEX(Caliber!B13:'Caliber'!C23,MATCH(INDIRECT(ADDRESS(ROW(),COLUMN()-1)),Caliber!B13:'Caliber'!B23,0),2)} -> 36 | Y7: {=INDEX(Caliber!C13:'Caliber'!D23,MATCH(INDIRECT(ADDRESS(ROW(),COLUMN()-2)),Caliber!B13:'Caliber'!B23,0),2)} -> 0.3 | Z7: [30,45,60][1]
A8: AKM | B8: 24 | C8: 1x3 | D8: N/A | E8: N/A | F8: TRUE | G8: 50 | H8: 125 | I8: 55 | J8: 45 | K8: 60 | L8: 55 | M8: 65 | N8: 25 | O8: 28 | P8: 38 | Q8: 7 | R8: 200 | S8: 0 | T8: 3 | U8: 1 | V8: 5 | W8: 7.62mm Soviet | X8: {=INDEX(Caliber!B13:'Caliber'!C23,MATCH(INDIRECT(ADDRESS(ROW(),COLUMN()-1)),Caliber!B13:'Caliber'!B23,0),2)} -> 43 | Y8: {=INDEX(Caliber!C13:'Caliber'!D23,MATCH(INDIRECT(ADDRESS(ROW(),COLUMN()-2)),Caliber!B13:'Caliber'!B23,0),2)} -> 0.6 | Z8: [30,40,75]
A9: Aks-74u | B9: 21 | C9: 1x3 | D9: N/A | E9: N/A | F9: TRUE | G9: 50 | H9: 125 | I9: 50 | J9: 41 | K9: 57 | L9: 48 | M9: 61 | N9: 37 | O9: 24 | P9: 34 | Q9: 10 | R9: 200 | S9: 0 | T9: 3 | U9: 1 | V9: 5 | W9: 5.45mm | X9: {=INDEX(Caliber!B13:'Caliber'!C23,MATCH(INDIRECT(ADDRESS(ROW(),COLUMN()-1)),Caliber!B13:'Caliber'!B23,0),2)} -> 36 | Y9: {=INDEX(Caliber!C13:'Caliber'!D23,MATCH(INDIRECT(ADDRESS(ROW(),COLUMN()-2)),Caliber!B13:'Caliber'!B23,0),2)} -> 0.3 | Z9: [30,45,60]
A10: Aks-74u (Sopmod) | B10: 19 | C10: 1x3 | D10: N/A | E10: N/A | F10: TRUE | G10: 50 | H10: 125 | I10: 70 | J10: 38 | K10: 55 | L10: 68 | M10: 61 | N10: 37 | O10: 29 | P10: 36 | Q10: 15 | R10: 200 | S10: 0 | T10: 3 | U10: 1 | V10: 5 | W10: 5.45mm | X10: {=INDEX(Caliber!B13:'Caliber'!C23,MATCH(INDIRECT(ADDRESS(ROW(),COLUMN()-1)),Caliber!B13:'Caliber'!B23,0),2)} -> 36 | Y10: {=INDEX(Caliber!C13:'Caliber'!D23,MATCH(INDIRECT(ADDRESS(ROW(),COLUMN()-2)),Caliber!B13:'Caliber'!B23,0),2)} -> 0.3 | Z10: [30,45,60]
A11: AR 18 | B11: 22 | C11: 1x3 | D11: N/A | E11: N/A | F11: TRUE | G11: 50 | H11: 125 | I11: 60 | J11: 35 | K11: 60 | L11: 55 | M11: 55 | N11: 40 | O11: 33 | P11: 30 | Q11: 11 | R11: 200 | S11: 0 | T11: 3 | U11: 1 | V11: 5 | W11: 5.56mm | X11: =INDEX(Caliber!B13:'Caliber'!C23,MATCH(W11,Caliber!B13:'Caliber'!B23,0),2) -> 37 | Y11: =INDEX(Caliber!C13:'Caliber'!D23,MATCH(W11,Caliber!B13:'Caliber'!B23,0),2) -> 0.4 | Z11: [30]
A12: AR 180 | B12: 22 | C12: 1x3 | D12: N/A | E12: N/A | F12: TRUE | G12: 50 | H12: 125 | I12: 70 | J12: 35 | K12: N/A | L12: 75 | M12: 45 | N12: N/A | O12: 34 | P12: 25 | Q12: N/A | R12: 200 | S12: 0 | T12: 1 | U12: 1 | V12: N/A | W12: 5.56mm | X12: =INDEX(Caliber!B13:'Caliber'!C23,MATCH(W12,Caliber!B13:'Caliber'!B23,0),2) -> 37 | Y12: =INDEX(Caliber!C13:'Caliber'!D23,MATCH(W12,Caliber!B13:'Caliber'!B23,0),2) -> 0.4 | Z12: [30]
A13: Famas | B13: 28 | C13: 1x3 | D13: 28000 | E13: N/A | F13: TRUE | G13: 50 | H13: 125 | I13: 55 | J13: 45 | K13: 40 | L13: 55 | M13: 45 | N13: 50 | O13: 18 | P13: 28 | Q13: 12 | R13: 200 | S13: 0 | T13: 3 | U13: 1 | V13: 5 | W13: 5.56mm | X13: =INDEX(Caliber!B13:'Caliber'!C23,MATCH(W13,Caliber!B13:'Caliber'!B23,0),2) -> 37 | Y13: =INDEX(Caliber!C13:'Caliber'!D23,MATCH(W13,Caliber!B13:'Caliber'!B23,0),2) -> 0.4 | Z13: [30][1] | AA13: Can load APAV40 Rifle Grenade
A14: Famas (Scoped) | B14: 30 | C14: 1x3 | D14: N/A | E14: N/A | F14: TRUE | G14: 50 | H14: 125 | I14: 70 | J14: 45 | K14: 40 | L14: 74 | M14: 40 | N14: 35 | O14: 23 | P14: 33 | Q14: 12 | R14: 200 | S14: 0 | T14: 3 | U14: 1 | V14: 5 | W14: 5.56mm | X14: =INDEX(Caliber!B13:'Caliber'!C23,MATCH(W14,Caliber!B13:'Caliber'!B23,0),2) -> 37 | Y14: =INDEX(Caliber!C13:'Caliber'!D23,MATCH(W14,Caliber!B13:'Caliber'!B23,0),2) -> 0.4 | Z14: [30][1] | AA14: Can load APAV40 Rifle Grenade
A15: FN FAL | B15: 38 | C15: 1x3 | D15: N/A | E15: N/A | F15: TRUE | G15: 50 | H15: 125 | I15: 80 | J15: 45 | K15: 65 | L15: 95 | M15: 50 | N15: 30 | O15: 50 | P15: 30 | Q15: 6 | R15: 200 | S15: 0 | T15: 1 | U15: 1 | V15: 3 | W15: 7.62mm Nato | X15: {=INDEX(Caliber!B13:'Caliber'!C23,MATCH(INDIRECT(ADDRESS(ROW(),COLUMN()-1)),Caliber!B13:'Caliber'!B23,0),2)} -> 45 | Y15: {=INDEX(Caliber!C13:'Caliber'!D23,MATCH(INDIRECT(ADDRESS(ROW(),COLUMN()-2)),Caliber!B13:'Caliber'!B23,0),2)} -> 0.6 | Z15: [20]
A16: FX-05 | B16: 19 | C16: 1x3 | D16: 17500 | E16: N/A | F16: TRUE | G16: 50 | H16: 125 | I16: 50 | J16: 35 | K16: 55 | L16: 55 | M16: 60 | N16: 40 | O16: 22 | P16: 32 | Q16: 10 | R16: 200 | S16: 0 | T16: 3 | U16: 1 | V16: 5 | W16: 5.56mm | X16: =INDEX(Caliber!B13:'Caliber'!C23,MATCH(W16,Caliber!B13:'Caliber'!B23,0),2) -> 37 | Y16: =INDEX(Caliber!C13:'Caliber'!D23,MATCH(W16,Caliber!B13:'Caliber'!B23,0),2) -> 0.4 | Z16: [30]
A17: FX-05 (Scoped) | B17: 21 | C17: 1x3 | D17: N/A | E17: N/A | F17: TRUE | G17: 50 | H17: 125 | I17: 65 | J17: 35 | K17: 55 | L17: 75 | M17: 55 | N17: 30 | O17: 27 | P17: 37 | Q17: 10 | R17: 200 | S17: 0 | T17: 3 | U17: 1 | V17: 5 | W17: 5.56mm | X17: =INDEX(Caliber!B13:'Caliber'!C23,MATCH(W17,Caliber!B13:'Caliber'!B23,0),2) -> 37 | Y17: =INDEX(Caliber!C13:'Caliber'!D23,MATCH(W17,Caliber!B13:'Caliber'!B23,0),2) -> 0.4 | Z17: [30]
A18: G11 | B18: 30 | C18: 1x3 | D18: 85000 | E18: N/A | F18: TRUE | G18: 50 | H18: 125 | I18: 60 | J18: 40 | K18: 45 | L18: 100 | M18: 80 | N18: 55 | O18: 45 | P18: 35 | Q18: 15 | R18: 200 | S18: 0 | T18: 3 | U18: 3 | V18: 5 | W18: 4.73 Caseless | X18: =INDEX(Caliber!B13:'Caliber'!C23,MATCH(W18,Caliber!B13:'Caliber'!B23,0),2) -> 35 | Y18: =INDEX(Caliber!C13:'Caliber'!D23,MATCH(W18,Caliber!B13:'Caliber'!B23,0),2) -> 0.3 | Z18: [50]
A19: G3 | B19: 33 | C19: 1x3 | D19: 36000 | E19: N/A | F19: TRUE | G19: 50 | H19: 125 | I19: 55 | J19: 45 | K19: 40 | L19: 75 | M19: 55 | N19: 35 | O19: 33 | P19: 36 | Q19: 11 | R19: 200 | S19: 0 | T19: 3 | U19: 1 | V19: 5 | W19: 7.62mm Nato | X19: {=INDEX(Caliber!B13:'Caliber'!C23,MATCH(INDIRECT(ADDRESS(ROW(),COLUMN()-1)),Caliber!B13:'Caliber'!B23,0),2)} -> 45 | Y19: {=INDEX(Caliber!C13:'Caliber'!D23,MATCH(INDIRECT(ADDRESS(ROW(),COLUMN()-2)),Caliber!B13:'Caliber'!B23,0),2)} -> 0.6 | Z19: [5,20,10]
A20: G36 | B20: 27 | C20: 1x3 | D20: 31000 | E20: N/A | F20: TRUE | G20: 50 | H20: 125 | I20: 70 | J20: 50 | K20: 55 | L20: 80 | M20: 60 | N20: 45 | O20: 33 | P20: 35 | Q20: 10 | R20: 200 | S20: 0 | T20: 3 | U20: 1 | V20: 5 | W20: 5.56mm | X20: =INDEX(Caliber!B13:'Caliber'!C23,MATCH(W20,Caliber!B13:'Caliber'!B23,0),2) -> 37 | Y20: =INDEX(Caliber!C13:'Caliber'!D23,MATCH(W20,Caliber!B13:'Caliber'!B23,0),2) -> 0.4 | Z20: [30][1]
A21: G36 (AG) | B21: 37 | C21: 1x3 | D21: N/A | E21: Auto | F21: TRUE | G21: 50 | H21: 125 | I21: 70 | J21: 50 | K21: 70 | L21: 80 | M21: 60 | N21: 45 | O21: 33 | P21: 35 | Q21: 16 | R21: 200 | S21: 0 | T21: 3 | U21: 1 | V21: 1 | W21: 5.56mm | X21: =INDEX(Caliber!B13:'Caliber'!C23,MATCH(W21,Caliber!B13:'Caliber'!B23,0),2) -> 37 | Y21: =INDEX(Caliber!C13:'Caliber'!D23,MATCH(W21,Caliber!B13:'Caliber'!B23,0),2) -> 0.4 | Z21: [30][1]
A22: G36C | B22: 23 | C22: 1x3 | D22: 31000 | E22: N/A | F22: TRUE | G22: 50 | H22: 125 | I22: 66 | J22: 46 | K22: 51 | L22: 78 | M22: 58 | N22: 45 | O22: 30 | P22: 32 | Q22: 10 | R22: 200 | S22: 0 | T22: 3 | U22: 1 | V22: 5 | W22: 5.56mm | X22: {=INDEX(Caliber!B13:'Caliber'!C23,MATCH(INDIRECT(ADDRESS(ROW(),COLUMN()-1)),Caliber!B13:'Caliber'!B23,0),2)} -> 37 | Y22: {=INDEX(Caliber!C13:'Caliber'!D23,MATCH(INDIRECT(ADDRESS(ROW(),COLUMN()-2)),Caliber!B13:'Caliber'!B23,0),2)} -> 0.4 | Z22: [30]
A23: HK416 | B23: 25 | C23: 1x3 | D23: 35000 | E23: N/A | F23: TRUE | G23: 50 | H23: 125 | I23: 55 | J23: 35 | K23: 65 | L23: 70 | M23: 65 | N23: 50 | O23: 30 | P23: 35 | Q23: 13 | R23: 200 | S23: 0 | T23: 3 | U23: 1 | V23: 5 | W23: 5.56mm | X23: =INDEX(Caliber!B13:'Caliber'!C23,MATCH(W23,Caliber!B13:'Caliber'!B23,0),2) -> 37 | Y23: =INDEX(Caliber!C13:'Caliber'!D23,MATCH(W23,Caliber!B13:'Caliber'!B23,0),2) -> 0.4 | Z23: [30]
A24: HK416 (M320) | B24: 37 | C24: 1x3 | D24: N/A | E24: Auto | F24: TRUE | G24: 50 | H24: 125 | I24: 55 | J24: 32 | K24: 65 | L24: 70 | M24: 65 | N24: 50 | O24: 30 | P24: 35 | Q24: 18 | R24: 200 | S24: 0 | T24: 3 | U24: 1 | V24: 1 | W24: 5.56mm | X24: =INDEX(Caliber!B13:'Caliber'!C23,MATCH(W24,Caliber!B13:'Caliber'!B23,0),2) -> 37 | Y24: =INDEX(Caliber!C13:'Caliber'!D23,MATCH(W24,Caliber!B13:'Caliber'!B23,0),2) -> 0.4 | Z24: [30][1]
A25: Hk416 (MASS) | B25: 34 | C25: 1x3 | D25: N/A | E25: Auto | F25: TRUE | G25: 50 | H25: 125 | I25: 55 | J25: 32 | K25: 30 | L25: 70 | M25: 65 | N25: 50 | O25: 30 | P25: 35 | Q25: 7 | R25: 200 | S25: 0 | T25: 3 | U25: 1 | V25: 1 | W25: 5.56mm | X25: =INDEX(Caliber!B13:'Caliber'!C23,MATCH(W25,Caliber!B13:'Caliber'!B23,0),2) -> 37 | Y25: =INDEX(Caliber!C13:'Caliber'!D23,MATCH(W25,Caliber!B13:'Caliber'!B23,0),2) -> 0.4 | Z25: [30][5]
A26: HK416 (Sopmod) | B26: 27 | C26: 1x3 | D26: N/A | E26: N/A | F26: TRUE | G26: 50 | H26: 125 | I26: 75 | J26: 32 | K26: 62 | L26: 90 | M26: 64 | N26: 50 | O26: 35 | P26: 40 | Q26: 13 | R26: 200 | S26: 0 | T26: 3 | U26: 1 | V26: 5 | W26: 5.56mm | X26: =INDEX(Caliber!B13:'Caliber'!C23,MATCH(W26,Caliber!B13:'Caliber'!B23,0),2) -> 37 | Y26: =INDEX(Caliber!C13:'Caliber'!D23,MATCH(W26,Caliber!B13:'Caliber'!B23,0),2) -> 0.4 | Z26: [30]
A27: HK417 | B27: 31 | C27: 1x3 | D27: 39000 | E27: N/A | F27: TRUE | G27: 50 | H27: 125 | I27: 65 | J27: 50 | K27: 65 | L27: 80 | M27: 65 | N27: 40 | O27: 37 | P27: 40 | Q27: 12 | R27: 200 | S27: 0 | T27: 3 | U27: 1 | V27: 5 | W27: 7.62mm Nato | X27: {=INDEX(Caliber!B13:'Caliber'!C23,MATCH(INDIRECT(ADDRESS(ROW(),COLUMN()-1)),Caliber!B13:'Caliber'!B23,0),2)} -> 45 | Y27: {=INDEX(Caliber!C13:'Caliber'!D23,MATCH(INDIRECT(ADDRESS(ROW(),COLUMN()-2)),Caliber!B13:'Caliber'!B23,0),2)} -> 0.6 | Z27: [10,20]
A28: HK417 (Scoped) | B28: 33 | C28: 1x3 | D28: N/A | E28: N/A | F28: TRUE | G28: 50 | H28: 125 | I28: 80 | J28: 50 | K28: 65 | L28: 100 | M28: 60 | N28: 30 | O28: 42 | P28: 45 | Q28: 12 | R28: 200 | S28: 0 | T28: 3 | U28: 1 | V28: 5 | W28: 7.62mm Nato | X28: {=INDEX(Caliber!B13:'Caliber'!C23,MATCH(INDIRECT(ADDRESS(ROW(),COLUMN()-1)),Caliber!B13:'Caliber'!B23,0),2)} -> 45 | Y28: {=INDEX(Caliber!C13:'Caliber'!D23,MATCH(INDIRECT(ADDRESS(ROW(),COLUMN()-2)),Caliber!B13:'Caliber'!B23,0),2)} -> 0.6 | Z28: [10,20]
A29: M14 EBR | B29: 30 | C29: 1x3 | D29: 17500 | E29: N/A | F29: TRUE | G29: 50 | H29: 125 | I29: 55 | J29: 45 | K29: 40 | L29: 70 | M29: 50 | N29: 20 | O29: 36 | P29: 20 | Q29: 11 | R29: 200 | S29: 0 | T29: 1 | U29: 1 | V29: 3 | W29: 7.62mm NATO | X29: {=INDEX(Caliber!B13:'Caliber'!C23,MATCH(INDIRECT(ADDRESS(ROW(),COLUMN()-1)),Caliber!B13:'Caliber'!B23,0),2)} -> 45 | Y29: {=INDEX(Caliber!C13:'Caliber'!D23,MATCH(INDIRECT(ADDRESS(ROW(),COLUMN()-2)),Caliber!B13:'Caliber'!B23,0),2)} -> 0.6 | Z29: [10,20]
A30: M14 EBR (Scoped) | B30: 32 | C30: 1x3 | D30: N/A | E30: N/A | F30: TRUE | G30: 50 | H30: 125 | I30: 70 | J30: 45 | K30: 40 | L30: 90 | M30: 65 | N30: 15 | O30: 50 | P30: 40 | Q30: 11 | R30: 200 | S30: 0 | T30: 1 | U30: 1 | V30: 3 | W30: 7.62mm Nato | X30: {=INDEX(Caliber!B13:'Caliber'!C23,MATCH(INDIRECT(ADDRESS(ROW(),COLUMN()-1)),Caliber!B13:'Caliber'!B23,0),2)} -> 45 | Y30: {=INDEX(Caliber!C13:'Caliber'!D23,MATCH(INDIRECT(ADDRESS(ROW(),COLUMN()-2)),Caliber!B13:'Caliber'!B23,0),2)} -> 0.6 | Z30: [10,20]
A31: M16A2 | B31: 22 | C31: 1x3 | D31: 12000 | E31: N/A | F31: TRUE | G31: 50 | H31: 125 | I31: 70 | J31: 40 | K31: 55 | L31: 70 | M31: 60 | N31: 45 | O31: 36 | P31: 32 | Q31: 26 | R31: 200 | S31: 0 | T31: 1 | U31: 1 | V31: 3 | W31: 5.56mm | X31: =INDEX(Caliber!B13:'Caliber'!C23,MATCH(W31,Caliber!B13:'Caliber'!B23,0),2) -> 37 | Y31: =INDEX(Caliber!C13:'Caliber'!D23,MATCH(W31,Caliber!B13:'Caliber'!B23,0),2) -> 0.4 | Z31: [30]
A32: M16A2 (M203) | B32: 30 | C32: 1x3 | D32: N/A | E32: Aimed | F32: TRUE | G32: 50 | H32: 125 | I32: 70 | J32: 40 | K32: 55 | L32: 40 | M32: 60 | N32: 45 | O32: 16 | P32: 32 | Q32: 26 | R32: 200 | S32: 0 | T32: 1 | U32: 1 | V32: 3 | W32: 5.56mm | X32: {=INDEX(Caliber!B13:'Caliber'!C23,MATCH(INDIRECT(ADDRESS(ROW(),COLUMN()-1)),Caliber!B13:'Caliber'!B23,0),2)} -> 37 | Y32: {=INDEX(Caliber!C13:'Caliber'!D23,MATCH(INDIRECT(ADDRESS(ROW(),COLUMN()-2)),Caliber!B13:'Caliber'!B23,0),2)} -> 0.4 | Z32: [30]
A33: M16A2 (Scoped) | B33: 24 | C33: 1x3 | D33: N/A | E33: N/A | F33: TRUE | G33: 50 | H33: 125 | I33: 60 | J33: 40 | K33: 60 | L33: 90 | M33: 50 | N33: 60 | O33: 60 | P33: 40 | Q33: 50 | R33: 200 | S33: 0 | T33: 1 | U33: 1 | V33: 3 | W33: 5.56mm | X33: {=INDEX(Caliber!B13:'Caliber'!C23,MATCH(INDIRECT(ADDRESS(ROW(),COLUMN()-1)),Caliber!B13:'Caliber'!B23,0),2)} -> 37 | Y33: {=INDEX(Caliber!C13:'Caliber'!D23,MATCH(INDIRECT(ADDRESS(ROW(),COLUMN()-2)),Caliber!B13:'Caliber'!B23,0),2)} -> 0.4 | Z33: [30]
A34: M4A1 | B34: 24 | C34: 1x3 | D34: 32000 | E34: N/A | F34: TRUE | G34: 50 | H34: 125 | I34: 60 | J34: 40 | K34: 65 | L34: 70 | M34: 65 | N34: 40 | O34: 24 | P34: 31 | Q34: 5 | R34: 200 | S34: 0 | T34: 3 | U34: 1 | V34: 5 | W34: 5.56mm | X34: =INDEX(Caliber!B13:'Caliber'!C23,MATCH(W34,Caliber!B13:'Caliber'!B23,0),2) -> 37 | Y34: =INDEX(Caliber!C13:'Caliber'!D23,MATCH(W34,Caliber!B13:'Caliber'!B23,0),2) -> 0.4 | Z34: [30]
A35: M4A1 (M320) | B35: 36 | C35: 1x3 | D35: N/A | E35: Auto | F35: TRUE | G35: 50 | H35: 125 | I35: 60 | J35: 40 | K35: 65 | L35: 70 | M35: 65 | N35: 50 | O35: 24 | P35: 31 | Q35: 18 | R35: 200 | S35: 0 | T35: 3 | U35: 1 | V35: 1 | W35: 5.56mm | X35: =INDEX(Caliber!B13:'Caliber'!C23,MATCH(W35,Caliber!B13:'Caliber'!B23,0),2) -> 37 | Y35: =INDEX(Caliber!C13:'Caliber'!D23,MATCH(W35,Caliber!B13:'Caliber'!B23,0),2) -> 0.4 | Z35: [30][1]
A36: M4A1 (MASS) | B36: 33 | C36: 1x3 | D36: N/A | E36: Auto | F36: TRUE | G36: 50 | H36: 125 | I36: 60 | J36: 40 | K36: 30 | L36: 70 | M36: 65 | N36: 50 | O36: 24 | P36: 31 | Q36: 7 | R36: 200 | S36: 0 | T36: 3 | U36: 1 | V36: 1 | W36: 5.56mm | X36: =INDEX(Caliber!B13:'Caliber'!C23,MATCH(W36,Caliber!B13:'Caliber'!B23,0),2) -> 37 | Y36: =INDEX(Caliber!C13:'Caliber'!D23,MATCH(W36,Caliber!B13:'Caliber'!B23,0),2) -> 0.4 | Z36: [30][5]
A37: M4A1 (Sopmod) | B37: 26 | C37: 1x3 | D37: N/A | E37: N/A | F37: TRUE | G37: 50 | H37: 125 | I37: 80 | J37: 37 | K37: 62 | L37: 90 | M37: 65 | N37: 40 | O37: 29 | P37: 41 | Q37: 10 | R37: 200 | S37: 0 | T37: 3 | U37: 1 | V37: 5 | W37: 5.56mm | X37: =INDEX(Caliber!B13:'Caliber'!C23,MATCH(W37,Caliber!B13:'Caliber'!B23,0),2) -> 37 | Y37: =INDEX(Caliber!C13:'Caliber'!D23,MATCH(W37,Caliber!B13:'Caliber'!B23,0),2) -> 0.4 | Z37: [30]
A38: Mk 18 Mod 0 | B38: 24 | C38: 1x3 | D38: 32000 | E38: N/A | F38: TRUE | G38: 50 | H38: 125 | I38: 60 | J38: 40 | K38: 55 | L38: 75 | M38: 65 | N38: 50 | O38: 24 | P38: 31 | Q38: 7 | R38: 200 | S38: 0 | T38: 3 | U38: 1 | V38: 5 | W38: 5.56mm | X38: =INDEX(Caliber!B13:'Caliber'!C23,MATCH(W38,Caliber!B13:'Caliber'!B23,0),2) -> 37 | Y38: =INDEX(Caliber!C13:'Caliber'!D23,MATCH(W38,Caliber!B13:'Caliber'!B23,0),2) -> 0.4 | Z38: [30]
A39: Mk 18 Mod 0 (M320) | B39: 36 | C39: 1x3 | D39: N/A | E39: Auto | F39: TRUE | G39: 50 | H39: 125 | I39: 60 | J39: 40 | K39: 65 | L39: 75 | M39: 65 | N39: 50 | O39: 24 | P39: 31 | Q39: 18 | R39: 200 | S39: 0 | T39: 3 | U39: 1 | V39: 1 | W39: 5.56mm | X39: =INDEX(Caliber!B13:'Caliber'!C23,MATCH(W39,Caliber!B13:'Caliber'!B23,0),2) -> 37 | Y39: =INDEX(Caliber!C13:'Caliber'!D23,MATCH(W39,Caliber!B13:'Caliber'!B23,0),2) -> 0.4 | Z39: [30][1]
A40: Mk 18 Mod 0 (MASS) | B40: 33 | C40: 1x3 | D40: N/A | E40: Auto | F40: TRUE | G40: 50 | H40: 125 | I40: 60 | J40: 40 | K40: 30 | L40: 75 | M40: 65 | N40: 50 | O40: 24 | P40: 31 | Q40: 7 | R40: 200 | S40: 0 | T40: 3 | U40: 1 | V40: 1 | W40: 5.56mm | X40: =INDEX(Caliber!B13:'Caliber'!C23,MATCH(W40,Caliber!B13:'Caliber'!B23,0),2) -> 37 | Y40: =INDEX(Caliber!C13:'Caliber'!D23,MATCH(W40,Caliber!B13:'Caliber'!B23,0),2) -> 0.4 | Z40: [30][5]
...

Sheet Snipers
A1: Name | B1: weight | C1: size | D1: Cost | E1: two handed | F1: Block both hands | G1: One hand pen. | H1: kneel bonus | I1: tuAimed | J1: tuSnap | K1: tuAuto | L1: accAimed | M1: accSnap | N1: accAuto | O1: rangeAimed | P1: rangeSnap | Q1: rangeAuto | R1: maxRange | S1: minRange | T1: Aimed shots | U1: snap shots | V1: auto shots | W1: Caliber | X1: Power | Y1: toArmorPre | Z1: Mag sizes | AA1: Notes:
A2: Hunting Rifle | B2: 15 | C2: 1x3 | D2: N/A | E2: TRUE | F2: TRUE | G2: N/A | H2: 145 | I2: 90 | J2: 75 | K2: N/A | L2: 105 | M2: 80 | N2: N/A | O2: 200 | P2: 25 | Q2: N/A | R2: 200 | S2: 2 | T2: 1 | U2: 1 | V2: N/A | W2: 22 Long Rifle | X2: =INDEX(Caliber!B13:'Caliber'!C23,MATCH(W2,Caliber!B13:'Caliber'!B23,0),2) -> 28 | Y2: =INDEX(Caliber!C13:'Caliber'!D23,MATCH(W2,Caliber!B13:'Caliber'!B23,0),2) -> 0 | Z2: [6]
A3: SKS | B3: 31 | C3: 1x3 | D3: N/A | E3: TRUE | F3: FALSE | G3: 35 | H3: 130 | I3: 85 | J3: 65 | K3: N/A | L3: 100 | M3: 60 | N3: N/A | O3: 200 | P3: 25 | Q3: N/A | R3: 200 | S3: 0 | T3: 1 | U3: 1 | V3: N/A | W3: 7.62mm Soviet | X3: =INDEX(Caliber!B13:'Caliber'!C23,MATCH(W3,Caliber!B13:'Caliber'!B23,0),2) -> 43 | Y3: =INDEX(Caliber!C13:'Caliber'!D23,MATCH(W3,Caliber!B13:'Caliber'!B23,0),2) -> 0.6 | Z3: [10]
A4: PSG 1 | B4: 50 | C4: 1x3 | D4: 42000 | E4: TRUE | F4: TRUE | G4: N/A | H4: 145 | I4: 90 | J4: 60 | K4: N/A | L4: 125 | M4: 85 | N4: N/A | O4: 200 | P4: 35 | Q4: N/A | R4: 200 | S4: 5 | T4: 1 | U4: 1 | V4: N/A | W4: 7.62mm Nato | X4: =INDEX(Caliber!B13:'Caliber'!C23,MATCH(W4,Caliber!B13:'Caliber'!B23,0),2) -> 45 | Y4: =INDEX(Caliber!C13:'Caliber'!D23,MATCH(W4,Caliber!B13:'Caliber'!B23,0),2) -> 0.6 | Z4: [5,10,20]
A5: MSG 90 | B5: 43 | C5: 1x3 | D5: 46000 | E5: TRUE | F5: TRUE | G5: N/A | H5: 130 | I5: 85 | J5: 55 | K5: 70 | L5: 130 | M5: 90 | N5: 50 | O5: 200 | P5: 35 | Q5: 15 | R5: 200 | S5: 3 | T5: 1 | U5: 1 | V5: 3 | W5: 7.62mm Nato | X5: =INDEX(Caliber!B13:'Caliber'!C23,MATCH(W5,Caliber!B13:'Caliber'!B23,0),2) -> 45 | Y5: =INDEX(Caliber!C13:'Caliber'!D23,MATCH(W5,Caliber!B13:'Caliber'!B23,0),2) -> 0.6 | Z5: [5,20]
A6: VSS | B6: 16 | C6: 1x3 | D6: 57000 | E6: TRUE | F6: FALSE | G6: 50 | H6: 130 | I6: 80 | J6: 50 | K6: 70 | L6: 115 | M6: 75 | N6: 55 | O6: 200 | P6: 35 | Q6: 18 | R6: 200 | S6: 2 | T6: 1 | U6: 1 | V6: 3 | W6: 9.39mm | X6: =INDEX(Caliber!B13:'Caliber'!C23,MATCH(W6,Caliber!B13:'Caliber'!B23,0),2) -> 51 | Y6: =INDEX(Caliber!C13:'Caliber'!D23,MATCH(W6,Caliber!B13:'Caliber'!B23,0),2) -> 0.7 | Z6: [10,20]
A7: Dragunov | B7: 35 | C7: 1x3 | D7: 43000 | E7: TRUE | F7: TRUE | G7: N/A | H7: 130 | I7: 85 | J7: 55 | K7: 70 | L7: 120 | M7: 90 | N7: 45 | O7: 200 | P7: 35 | Q7: 20 | R7: 200 | S7: 5 | T7: 1 | U7: 1 | V7: 3 | W7: 7.62mm Soviet MMR | X7: =INDEX(Caliber!B13:'Caliber'!C23,MATCH(W7,Caliber!B13:'Caliber'!B23,0),2) -> 49 | Y7: =INDEX(Caliber!C13:'Caliber'!D23,MATCH(W7,Caliber!B13:'Caliber'!B23,0),2) -> 0.7 | Z7: [10]
A8: OSV 96 | B8: 65 | C8: 1x3 | D8: 62000 | E8: TRUE | F8: TRUE | G8: N/A | H8: 150 | I8: 80 | J8: 65 | K8: N/A | L8: 115 | M8: 70 | N8: N/A | O8: 200 | P8: 50 | Q8: N/A | R8: 200 | S8: 5 | T8: 1 | U8: 1 | V8: N/A | W8: 12.7mm | X8: =INDEX(Caliber!B13:'Caliber'!C23,MATCH(W8,Caliber!B13:'Caliber'!B23,0),2) -> 75 | Y8: =INDEX(Caliber!C13:'Caliber'!D23,MATCH(W8,Caliber!B13:'Caliber'!B23,0),2) -> 1 | Z8: [5]
A9: Sako TRG | B9: 40 | C9: 1x3 | D9: 52000 | E9: TRUE | F9: TRUE | G9: N/A | H9: 145 | I9: 90 | J9: 65 | K9: N/A | L9: 150 | M9: 100 | N9: N/A | O9: 200 | P9: 50 | Q9: N/A | R9: 200 | S9: 10 | T9: 1 | U9: 1 | V9: N/A | W9: .338 Lapua | X9: =INDEX(Caliber!B13:'Caliber'!C23,MATCH(W9,Caliber!B13:'Caliber'!B23,0),2) -> 61 | Y9: =INDEX(Caliber!C13:'Caliber'!D23,MATCH(W9,Caliber!B13:'Caliber'!B23,0),2) -> 0.8 | Z9: [5]
A10: AWP | B10: 47 | C10: 1x3 | D10: 47500 | E10: TRUE | F10: TRUE | G10: N/A | H10: 145 | I10: 80 | J10: 55 | K10: N/A | L10: 115 | M10: 80 | N10: N/A | O10: 200 | P10: 33 | Q10: N/A | R10: 200 | S10: 5 | T10: 1 | U10: 1 | V10: N/A | W10: 7.62mm Nato | X10: =INDEX(Caliber!B13:'Caliber'!C23,MATCH(W10,Caliber!B13:'Caliber'!B23,0),2) -> 45 | Y10: =INDEX(Caliber!C13:'Caliber'!D23,MATCH(W10,Caliber!B13:'Caliber'!B23,0),2) -> 0.6 | Z10: [10]
A11: AWM | B11: 47 | C11: 1x3 | D11: 51000 | E11: TRUE | F11: TRUE | G11: N/A | H11: 145 | I11: 85 | J11: 65 | K11: N/A | L11: 135 | M11: 85 | N11: N/A | O11: 200 | P11: 65 | Q11: N/A | R11: 200 | S11: 10 | T11: 1 | U11: 1 | V11: N/A | W11: .338 Lapua | X11: =INDEX(Caliber!B13:'Caliber'!C23,MATCH(W11,Caliber!B13:'Caliber'!B23,0),2) -> 61 | Y11: =INDEX(Caliber!C13:'Caliber'!D23,MATCH(W11,Caliber!B13:'Caliber'!B23,0),2) -> 0.8 | Z11: [5]
A12: M24 SWS | B12: 44 | C12: 1x3 | D12: 44000 | E12: TRUE | F12: TRUE | G12: N/A | H12: 145 | I12: 80 | J12: 55 | K12: N/A | L12: 110 | M12: 85 | N12: N/A | O12: 200 | P12: 35 | Q12: N/A | R12: 200 | S12: 5 | T12: 1 | U12: 1 | V12: N/A | W12: 7.62mm Nato | X12: =INDEX(Caliber!B13:'Caliber'!C23,MATCH(W12,Caliber!B13:'Caliber'!B23,0),2) -> 45 | Y12: =INDEX(Caliber!C13:'Caliber'!D23,MATCH(W12,Caliber!B13:'Caliber'!B23,0),2) -> 0.6 | Z12: [5]
A13: M82 | B13: 70 | C13: 1x3 | D13: 60000 | E13: TRUE | F13: TRUE | G13: N/A | H13: 150 | I13: 90 | J13: 70 | K13: N/A | L13: 130 | M13: 75 | N13: N/A | O13: 200 | P13: 50 | Q13: N/A | R13: 200 | S13: 12 | T13: 1 | U13: 1 | V13: N/A | W13: .50 BMG | X13: =INDEX(Caliber!B13:'Caliber'!C23,MATCH(W13,Caliber!B13:'Caliber'!B23,0),2) -> 70 | Y13: =INDEX(Caliber!C13:'Caliber'!D23,MATCH(W13,Caliber!B13:'Caliber'!B23,0),2) -> 1 | Z13: [5,10]
A14: M1 Garand | B14: 35 | C14: 1x3 | D14: N/A | E14: TRUE | F14: TRUE | G14: N/A | H14: 130 | I14: 80 | J14: 45 | K14: N/A | L14: 80 | M14: 60 | N14: N/A | O14: 30 | P14: 20 | Q14: N/A | R14: 200 | S14: 0 | T14: 1 | U14: 1 | V14: N/A | W14: .30-06 | X14: =INDEX(Caliber!B13:'Caliber'!C24,MATCH(W14,Caliber!B13:'Caliber'!B24,0),2) -> 40 | Y14: =INDEX(Caliber!C13:'Caliber'!D24,MATCH(W14,Caliber!B13:'Caliber'!B24,0),2) -> 0.5 | Z14: [8] | AA14: Unscoped, Sling
A15: M1D Garand | B15: 37 | C15: 1x3 | D15: N/A | E15: TRUE | F15: TRUE | G15: N/A | H15: 130 | I15: 85 | J15: 45 | K15: N/A | L15: 100 | M15: 55 | N15: N/A | O15: 200 | P15: 25 | Q15: N/A | R15: 200 | S15: 0 | T15: 1 | U15: 1 | V15: N/A | W15: .30-06 | X15: =INDEX(Caliber!B13:'Caliber'!C24,MATCH(W15,Caliber!B13:'Caliber'!B24,0),2) -> 40 | Y15: =INDEX(Caliber!C13:'Caliber'!D24,MATCH(W15,Caliber!B13:'Caliber'!B24,0),2) -> 0.5 | Z15: [8] | AA15: Sling
A16: Styer Scout | B16: 24 | C16: 1x3 | D16: 45000 | E16: TRUE | F16: TRUE | G16: N/A | H16: 145 | I16: 70 | J16: 50 | K16: N/A | L16: 115 | M16: 85 | N16: N/A | O16: 200 | P16: 35 | Q16: N/A | R16: 200 | S16: 5 | T16: 1 | U16: 1 | V16: N/A | W16: 5.56mm | X16: =INDEX(Caliber!B13:'Caliber'!C23,MATCH(W16,Caliber!B13:'Caliber'!B23,0),2) -> 37 | Y16: =INDEX(Caliber!C13:'Caliber'!D23,MATCH(W16,Caliber!B13:'Caliber'!B23,0),2) -> 0.4 | Z16: [10]
A17: SSG 08 | B17: 27 | C17: 1x3 | D17: 49000 | E17: TRUE | F17: TRUE | G17: N/A | H17: 145 | I17: 75 | J17: 50 | K17: N/A | L17: 125 | M17: 90 | N17: N/A | O17: 200 | P17: 35 | Q17: N/A | R17: 200 | S17: 5 | T17: 1 | U17: 1 | V17: N/A | W17: 7.62mm Nato | X17: =INDEX(Caliber!B13:'Caliber'!C23,MATCH(W17,Caliber!B13:'Caliber'!B23,0),2) -> 45 | Y17: =INDEX(Caliber!C13:'Caliber'!D23,MATCH(W17,Caliber!B13:'Caliber'!B23,0),2) -> 0.6 | Z17: [10]
X18: =INDEX(Caliber!B13:'Caliber'!C23,MATCH(W18,Caliber!B13:'Caliber'!B23,0),2) -> #N/A | Y18: =INDEX(Caliber!C13:'Caliber'!D23,MATCH(W18,Caliber!B13:'Caliber'!B23,0),2) -> #N/A
X19: =INDEX(Caliber!B13:'Caliber'!C23,MATCH(W19,Caliber!B13:'Caliber'!B23,0),2) -> #N/A | Y19: =INDEX(Caliber!C13:'Caliber'!D23,MATCH(W19,Caliber!B13:'Caliber'!B23,0),2) -> #N/A
X20: =INDEX(Caliber!B13:'Caliber'!C23,MATCH(W20,Caliber!B13:'Caliber'!B23,0),2) -> #N/A | Y20: =INDEX(Caliber!C13:'Caliber'!D23,MATCH(W20,Caliber!B13:'Caliber'!B23,0),2) -> #N/A
X21: =INDEX(Caliber!B13:'Caliber'!C23,MATCH(W21,Caliber!B13:'Caliber'!B23,0),2) -> #N/A | Y21: =INDEX(Caliber!C13:'Caliber'!D23,MATCH(W21,Caliber!B13:'Caliber'!B23,0),2) -> #N/A
X22: =INDEX(Caliber!B13:'Caliber'!C23,MATCH(W22,Caliber!B13:'Caliber'!B23,0),2) -> #N/A | Y22: =INDEX(Caliber!C13:'Caliber'!D23,MATCH(W22,Caliber!B13:'Caliber'!B23,0),2) -> #N/A
X23: =INDEX(Caliber!B13:'Caliber'!C23,MATCH(W23,Caliber!B13:'Caliber'!B23,0),2) -> #N/A | Y23: =INDEX(Caliber!C13:'Caliber'!D23,MATCH(W23,Caliber!B13:'Caliber'!B23,0),2) -> #N/A
X24: =INDEX(Caliber!B13:'Caliber'!C23,MATCH(W24,Caliber!B13:'Caliber'!B23,0),2) -> #N/A | Y24: =INDEX(Caliber!C13:'Caliber'!D23,MATCH(W24,Caliber!B13:'Caliber'!B23,0),2) -> #N/A
X25: =INDEX(Caliber!B13:'Caliber'!C23,MATCH(W25,Caliber!B13:'Caliber'!B23,0),2) -> #N/A | Y25: =INDEX(Caliber!C13:'Caliber'!D23,MATCH(W25,Caliber!B13:'Caliber'!B23,0),2) -> #N/A
X26: =INDEX(Caliber!B13:'Caliber'!C23,MATCH(W26,Caliber!B13:'Caliber'!B23,0),2) -> #N/A | Y26: =INDEX(Caliber!C13:'Caliber'!D23,MATCH(W26,Caliber!B13:'Caliber'!B23,0),2) -> #N/A
X27: =INDEX(Caliber!B13:'Caliber'!C23,MATCH(W27,Caliber!B13:'Caliber'!B23,0),2) -> #N/A | Y27: =INDEX(Caliber!C13:'Caliber'!D23,MATCH(W27,Caliber!B13:'Caliber'!B23,0),2) -> #N/A
X28: =INDEX(Caliber!B13:'Caliber'!C23,MATCH(W28,Caliber!B13:'Caliber'!B23,0),2) -> #N/A | Y28: =INDEX(Caliber!C13:'Caliber'!D23,MATCH(W28,Caliber!B13:'Caliber'!B23,0),2) -> #N/A
X29: =INDEX(Caliber!B13:'Caliber'!C23,MATCH(W29,Caliber!B13:'Caliber'!B23,0),2) -> #N/A | Y29: =INDEX(Caliber!C13:'Caliber'!D23,MATCH(W29,Caliber!B13:'Caliber'!B23,0),2) -> #N/A
X30: =INDEX(Caliber!B13:'Caliber'!C23,MATCH(W30,Caliber!B13:'Caliber'!B23,0),2) -> #N/A | Y30: =INDEX(Caliber!C13:'Caliber'!D23,MATCH(W30,Caliber!B13:'Caliber'!B23,0),2) -> #N/A

Sheet Shotguns
A1: Name | B1: weight | C1: size | D1: Cost | E1: two handed | F1: One hand pen. | G1: kneel bonus | H1: Choke | I1: tuAimed | J1: tuSnap | K1: tuAuto | L1: accAimed | M1: accSnap | N1: accAuto | O1: rangeAimed | P1: rangeSnap | Q1: rangeAuto | R1: maxRange | S1: minRange | T1: Aimed shots | U1: snap shots | V1: auto shots | W1: Caliber | X1: Power | Y1: Pellets | Z1: toArmorPre | AA1: Mag sizes | AB1: Notes:
A2: Double Barrel | B2: 32 | C2: 1x3 | D2: N/A | E2: TRUE | F2: 35 | G2: 115 | H2: 10 | I2: 65 | J2: 35 | K2: N/A | L2: 80 | M2: 40 | N2: N/A | O2: 14 | P2: 7 | Q2: N/A | R2: 30 | S2: 0 | T2: 1 | U2: 1 | V2: N/A | W2: 12G Buckshot | X2: =INDEX(Caliber!B26:'Caliber'!C33,MATCH(W2,Caliber!B26:'Caliber'!B33,0),2) -> 18 | Y2: =INDEX(Caliber!B26:'Caliber'!D33,MATCH(W2,Caliber!B26:'Caliber'!B33,0),3) -> 10 | Z2: =INDEX(Caliber!B26:'Caliber'!F33,MATCH(W2,Caliber!B26:'Caliber'!B33,0),5) -> 0 | AA2: [2]
A3: Serbu | B3: 12 | C3: 1x2 | D3: 30000 | E3: TRUE | F3: 80 | G3: 100 | H3: 0 | I3: 60 | J3: 30 | K3: N/A | L3: 75 | M3: 45 | N3: N/A | O3: 12 | P3: 5 | Q3: N/A | R3: 30 | S3: 0 | T3: 1 | U3: 1 | V3: N/A | W3: 12G Buckshot | X3: =INDEX(Caliber!B26:'Caliber'!C33,MATCH(W3,Caliber!B26:'Caliber'!B33,0),2) -> 18 | Y3: =INDEX(Caliber!B26:'Caliber'!D33,MATCH(W3,Caliber!B26:'Caliber'!B33,0),3) -> 10 | Z3: =INDEX(Caliber!B26:'Caliber'!F33,MATCH(W3,Caliber!B26:'Caliber'!B33,0),5) -> 0 | AA3: [5] | AB3: Breach ammo
A4: Remington 870 | B4: 25 | C4: 1x3 | D4: 21000 | E4: TRUE | F4: 35 | G4: 115 | H4: 5 | I4: 50 | J4: 30 | K4: N/A | L4: 95 | M4: 50 | N4: N/A | O4: 15 | P4: 7 | Q4: N/A | R4: 30 | S4: 0 | T4: 1 | U4: 1 | V4: N/A | W4: 12G Buckshot | X4: =INDEX(Caliber!B26:'Caliber'!C33,MATCH(W4,Caliber!B26:'Caliber'!B33,0),2) -> 18 | Y4: =INDEX(Caliber!B26:'Caliber'!D33,MATCH(W4,Caliber!B26:'Caliber'!B33,0),3) -> 10 | Z4: =INDEX(Caliber!B26:'Caliber'!F33,MATCH(W4,Caliber!B26:'Caliber'!B33,0),5) -> 0 | AA4: [8] | AB4: NL, Slug & Inc ammo
A5: Spas-12 | B5: 33 | C5: 1x3 | D5: 28000 | E5: TRUE | F5: 35 | G5: 115 | H5: 5 | I5: 55 | J5: 35 | K5: N/A | L5: 110 | M5: 55 | N5: N/A | O5: 18 | P5: 10 | Q5: N/A | R5: 30 | S5: 0 | T5: 1 | U5: 1 | V5: N/A | W5: 12G Buckshot | X5: =INDEX(Caliber!B26:'Caliber'!C33,MATCH(W5,Caliber!B26:'Caliber'!B33,0),2) -> 18 | Y5: =INDEX(Caliber!B26:'Caliber'!D33,MATCH(W5,Caliber!B26:'Caliber'!B33,0),3) -> 10 | Z5: =INDEX(Caliber!B26:'Caliber'!F33,MATCH(W5,Caliber!B26:'Caliber'!B33,0),5) -> 0 | AA5: [8] | AB5: NL, Slug & Inc ammo
A6: KS-23 | B6: 30 | C6: 1x3 | D6: 30000 | E6: TRUE | F6: 35 | G6: 115 | H6: 0 | I6: 55 | J6: 25 | K6: N/A | L6: 100 | M6: 60 | N6: N/A | O6: 20 | P6: 10 | Q6: N/A | R6: 30 | S6: 0 | T6: 1 | U6: 1 | V6: N/A | W6: Shrapnel-25 (4G) | X6: =INDEX(Caliber!B26:'Caliber'!C33,MATCH(W6,Caliber!B26:'Caliber'!B33,0),2) -> 18 | Y6: =INDEX(Caliber!B26:'Caliber'!D33,MATCH(W6,Caliber!B26:'Caliber'!B33,0),3) -> 20 | Z6: =INDEX(Caliber!B26:'Caliber'!F33,MATCH(W6,Caliber!B26:'Caliber'!B33,0),5) -> 0 | AA6: [3] | AB6: NL & Slug ammo
A7: Origin 12 | B7: 37 | C7: 1x3 | D7: 51000 | E7: TRUE | F7: 35 | G7: 115 | H7: 0 | I7: 40 | J7: 15 | K7: N/A | L7: 80 | M7: 50 | N7: N/A | O7: 15 | P7: 7 | Q7: N/A | R7: 30 | S7: 0 | T7: 1 | U7: 1 | V7: N/A | W7: 12G Buckshot | X7: =INDEX(Caliber!B26:'Caliber'!C33,MATCH(W7,Caliber!B26:'Caliber'!B33,0),2) -> 18 | Y7: =INDEX(Caliber!B26:'Caliber'!D33,MATCH(W7,Caliber!B26:'Caliber'!B33,0),3) -> 10 | Z7: =INDEX(Caliber!B26:'Caliber'!F33,MATCH(W7,Caliber!B26:'Caliber'!B33,0),5) -> 0 | AA7: [8,20,30] | AB7: NL & Slug ammo (8rnd only)
A8: AA-12 | B8: 46 | C8: 1x3 | D8: 40000 | E8: TRUE | F8: 35 | G8: 115 | H8: 0 | I8: 40 | J8: 75 | K8: 50 | L8: 80 | M8: 100 | N8: 65 | O8: 12 | P8: 18 | Q8: 7 | R8: 30 | S8: 0 | T8: 3 | U8: 1 | V8: 5 | W8: 12G Buckshot | X8: =INDEX(Caliber!B26:'Caliber'!C33,MATCH(W8,Caliber!B26:'Caliber'!B33,0),2) -> 18 | Y8: =INDEX(Caliber!B26:'Caliber'!D33,MATCH(W8,Caliber!B26:'Caliber'!B33,0),3) -> 10 | Z8: =INDEX(Caliber!B26:'Caliber'!F33,MATCH(W8,Caliber!B26:'Caliber'!B33,0),5) -> 0 | AA8: [8,20,30] | AB8: NL & Slug ammo (8rnd only)
A9: USAS 12 | B9: 42 | C9: 1x3 | D9: 32000 | E9: TRUE | F9: 35 | G9: 115 | H9: 0 | I9: 30 | J9: 65 | K9: 50 | L9: 60 | M9: 80 | N9: 50 | O9: 10 | P9: 14 | Q9: 4 | R9: 30 | S9: 0 | T9: 3 | U9: 1 | V9: 5 | W9: 12G Buckshot | X9: =INDEX(Caliber!B26:'Caliber'!C33,MATCH(W9,Caliber!B26:'Caliber'!B33,0),2) -> 18 | Y9: =INDEX(Caliber!B26:'Caliber'!D33,MATCH(W9,Caliber!B26:'Caliber'!B33,0),3) -> 10 | Z9: =INDEX(Caliber!B26:'Caliber'!F33,MATCH(W9,Caliber!B26:'Caliber'!B33,0),5) -> 0 | AA9: [8,20,30] | AB9: NL & Slug ammo (8rnd only)
A10: Saiga 12 | B10: 28 | C10: 1x3 | D10: 43000 | E10: TRUE | F10: 35 | G10: 115 | H10: 0 | I10: 25 | J10: 65 | K10: 45 | L10: 70 | M10: 90 | N10: 35 | O10: 9 | P10: 13 | Q10: 6 | R10: 30 | S10: 0 | T10: 3 | U10: 1 | V10: 5 | W10: 12G Buckshot | X10: =INDEX(Caliber!B26:'Caliber'!C33,MATCH(W10,Caliber!B26:'Caliber'!B33,0),2) -> 18 | Y10: =INDEX(Caliber!B26:'Caliber'!D33,MATCH(W10,Caliber!B26:'Caliber'!B33,0),3) -> 10 | Z10: =INDEX(Caliber!B26:'Caliber'!F33,MATCH(W10,Caliber!B26:'Caliber'!B33,0),5) -> 0 | AA10: [8,20,30] | AB10: NL & Slug ammo (8rnd only)
A11: M3 | B11: 24 | C11: 1x3 | D11: 21000 | E11: TRUE | F11: N/A | G11: 115 | H11: 30 | I11: 80 | J11: 45 | K11: N/A | L11: 115 | M11: 80 | N11: N/A | O11: 20 | P11: 12 | Q11: N/A | R11: 35 | S11: 0 | T11: 1 | U11: 1 | V11: N/A | W11: 12G Buckshot | X11: {=INDEX(Caliber!B26:'Caliber'!C33,MATCH(INDIRECT(ADDRESS(ROW(),COLUMN()-1)),Caliber!B26:'Caliber'!B33,0),2)} -> 18 | Y11: {=INDEX(Caliber!B26:'Caliber'!D33,MATCH(INDIRECT(ADDRESS(ROW(),COLUMN()-2)),Caliber!B26:'Caliber'!B33,0),3)} -> 10 | Z11: {=INDEX(Caliber!B26:'Caliber'!F33,MATCH(INDIRECT(ADDRESS(ROW(),COLUMN()-3)),Caliber!B26:'Caliber'!B33,0),5)} -> 0 | AA11: [8] | AB11: NL, Slug & Inc ammo
A12: M26 MASS | B12: 8 | C12: 1x2 | D12: 18000 | E12: TRUE | F12: N/A | G12: 115 | H12: 0 | I12: N/A | J12: 30 | K12: N/A | L12: N/A | M12: 50 | N12: N/A | O12: N/A | P12: 7 | Q12: N/A | R12: 30 | S12: 0 | T12: N/A | U12: 1 | V12: N/A | W12: 12G Buckshot | X12: {=INDEX(Caliber!B26:'Caliber'!C33,MATCH(INDIRECT(ADDRESS(ROW(),COLUMN()-1)),Caliber!B26:'Caliber'!B33,0),2)} -> 18 | Y12: {=INDEX(Caliber!B26:'Caliber'!D33,MATCH(INDIRECT(ADDRESS(ROW(),COLUMN()-2)),Caliber!B26:'Caliber'!B33,0),3)} -> 10 | Z12: {=INDEX(Caliber!B26:'Caliber'!F33,MATCH(INDIRECT(ADDRESS(ROW(),COLUMN()-3)),Caliber!B26:'Caliber'!B33,0),5)} -> 0 | AA12: [5]

Sheet LMGs
A1: Name | B1: weight | C1: size | D1: Cost | E1: two handed | F1: Block both hands | G1: One hand pen. | H1: kneel bonus | I1: tuAimed | J1: tuSnap | K1: tuAuto | L1: accAimed | M1: accSnap | N1: accAuto | O1: rangeAimed | P1: rangeSnap | Q1: rangeAuto | R1: maxRange | S1: minRange | T1: Movement pen. | U1: Aimed shots | V1: snap shots | W1: auto shots | X1: Caliber | Y1: Power | Z1: toArmorPre | AA1: Mag sizes | AB1: Notes:
A2: M60 | B2: 65 | C2: 2x3 | D2: N/A | E2: TRUE | F2: TRUE | G2: N/A | H2: 145 | I2: N/A | J2: 50 | K2: 75 | L2: N/A | M2: 45 | N2: 20 | O2: N/A | P2: 28 | Q2: 14 | R2: 200 | S2: 5 | T2: 85 | U2: N/A | V2: 5 | W2: 15 | X2: 7.62mm NATO | Y2: {=INDEX(Caliber!B13:'Caliber'!C23,MATCH(INDIRECT(ADDRESS(ROW(),COLUMN()-1)),Caliber!B13:'Caliber'!B23,0),2)} -> 45 | Z2: {=INDEX(Caliber!C13:'Caliber'!D23,MATCH(INDIRECT(ADDRESS(ROW(),COLUMN()-2)),Caliber!B13:'Caliber'!B23,0),2)} -> 0.6 | AA2: [50,100]
A3: FN Minimi | B3: 56 | C3: 2x3 | D3: N/A | E3: TRUE | F3: TRUE | G3: N/A | H3: 145 | I3: N/A | J3: 48 | K3: 70 | L3: N/A | M3: 55 | N3: 32 | O3: N/A | P3: 30 | Q3: 15 | R3: 200 | S3: 5 | T3: 85 | U3: N/A | V3: 5 | W3: 15 | X3: 5.56mm | Y3: {=INDEX(Caliber!B13:'Caliber'!C23,MATCH(INDIRECT(ADDRESS(ROW(),COLUMN()-1)),Caliber!B13:'Caliber'!B23,0),2)} -> 37 | Z3: {=INDEX(Caliber!C13:'Caliber'!D23,MATCH(INDIRECT(ADDRESS(ROW(),COLUMN()-2)),Caliber!B13:'Caliber'!B23,0),2)} -> 0.4 | AA3: [30,50,100]
A4: PKP Pecheneg | B4: 59 | C4: 2x3 | D4: 56500 | E4: TRUE | F4: TRUE | G4: N/A | H4: 145 | I4: N/A | J4: 55 | K4: 80 | L4: N/A | M4: 50 | N4: 20 | O4: N/A | P4: 40 | Q4: 20 | R4: 200 | S4: 5 | T4: 85 | U4: N/A | V4: 5 | W4: 15 | X4: 7.62mm Soviet mmr | Y4: {=INDEX(Caliber!B13:'Caliber'!C23,MATCH(INDIRECT(ADDRESS(ROW(),COLUMN()-1)),Caliber!B13:'Caliber'!B23,0),2)} -> 49 | Z4: {=INDEX(Caliber!C13:'Caliber'!D23,MATCH(INDIRECT(ADDRESS(ROW(),COLUMN()-2)),Caliber!B13:'Caliber'!B23,0),2)} -> 0.7 | AA4: [50,100]
A5: MK 48 | B5: 60 | C5: 2x3 | D5: 65000 | E5: TRUE | F5: TRUE | G5: N/A | H5: 145 | I5: N/A | J5: 50 | K5: 70 | L5: N/A | M5: 55 | N5: 25 | O5: N/A | P5: 35 | Q5: 18 | R5: 200 | S5: 5 | T5: 85 | U5: N/A | V5: 5 | W5: 15 | X5: 7.62mm NATO | Y5: {=INDEX(Caliber!B13:'Caliber'!C23,MATCH(INDIRECT(ADDRESS(ROW(),COLUMN()-1)),Caliber!B13:'Caliber'!B23,0),2)} -> 45 | Z5: {=INDEX(Caliber!C13:'Caliber'!D23,MATCH(INDIRECT(ADDRESS(ROW(),COLUMN()-2)),Caliber!B13:'Caliber'!B23,0),2)} -> 0.6 | AA5: [50,100]
A6: M249 Para | B6: 52 | C6: 2x3 | D6: 53000 | E6: TRUE | F6: TRUE | G6: N/A | H6: 145 | I6: N/A | J6: 45 | K6: 70 | L6: N/A | M6: 60 | N6: 30 | O6: N/A | P6: 30 | Q6: 15 | R6: 200 | S6: 5 | T6: 85 | U6: N/A | V6: 5 | W6: 15 | X6: 5.56mm | Y6: {=INDEX(Caliber!B13:'Caliber'!C23,MATCH(INDIRECT(ADDRESS(ROW(),COLUMN()-1)),Caliber!B13:'Caliber'!B23,0),2)} -> 37 | Z6: {=INDEX(Caliber!C13:'Caliber'!D23,MATCH(INDIRECT(ADDRESS(ROW(),COLUMN()-2)),Caliber!B13:'Caliber'!B23,0),2)} -> 0.4 | AA6: [30,50,100]
A7: Negev | B7: 49 | C7: 2x3 | D7: 55000 | E7: TRUE | F7: TRUE | G7: N/A | H7: 145 | I7: N/A | J7: 40 | K7: 70 | L7: N/A | M7: 65 | N7: 28 | O7: N/A | P7: 30 | Q7: 15 | R7: 200 | S7: 5 | T7: 85 | U7: N/A | V7: 5 | W7: 15 | X7: 5.56mm | Y7: {=INDEX(Caliber!B13:'Caliber'!C23,MATCH(INDIRECT(ADDRESS(ROW(),COLUMN()-1)),Caliber!B13:'Caliber'!B23,0),2)} -> 37 | Z7: {=INDEX(Caliber!C13:'Caliber'!D23,MATCH(INDIRECT(ADDRESS(ROW(),COLUMN()-2)),Caliber!B13:'Caliber'!B23,0),2)} -> 0.4 | AA7: [50,100]
A8: RPK 74 | B8: 38 | C8: 2x3 | D8: 49000 | E8: TRUE | F8: TRUE | G8: N/A | H8: 145 | I8: N/A | J8: 55 | K8: 75 | L8: N/A | M8: 65 | N8: 35 | O8: N/A | P8: 30 | Q8: 15 | R8: 200 | S8: 5 | T8: 85 | U8: N/A | V8: 5 | W8: 15 | X8: 5.45mm | Y8: {=INDEX(Caliber!B13:'Caliber'!C23,MATCH(INDIRECT(ADDRESS(ROW(),COLUMN()-1)),Caliber!B13:'Caliber'!B23,0),2)} -> 36 | Z8: {=INDEX(Caliber!C13:'Caliber'!D23,MATCH(INDIRECT(ADDRESS(ROW(),COLUMN()-2)),Caliber!B13:'Caliber'!B23,0),2)} -> 0.3 | AA8: [30,45]
A9: CBJ-MS SAW | B9: 24 | C9: 2x2 | D9: N/A | E9: TRUE | F9: FALSE | G9: 80 | H9: 145 | I9: 35 | J9: 40 | K9: 70 | L9: 60 | M9: 45 | N9: 35 | O9: 30 | P9: 10 | Q9: 10 | R9: 40 | S9: 4 | T9: 85 | U9: 2 | V9: 5 | W9: 15 | X9: 6.5mm CBJ | Y9: {=INDEX(Caliber!B2:'Caliber'!C11,MATCH(INDIRECT(ADDRESS(ROW(),COLUMN()-1)),Caliber!B2:'Caliber'!B11,0),2)} -> 30 | Z9: {=INDEX(Caliber!C2:'Caliber'!D11,MATCH(INDIRECT(ADDRESS(ROW(),COLUMN()-2)),Caliber!B2:'Caliber'!B11,0),2)} -> 0.35 | AA9: [30,100]
A10: FN MAG | B10: 78 | C10: 2x3 | D10: N/A | E10: TRUE | F10: TRUE | G10: N/A | H10: 145 | I10: N/A | J10: 70 | K10: 80 | L10: N/A | M10: 60 | N10: 40 | O10: N/A | P10: 35 | Q10: 20 | R10: 200 | S10: 5 | T10: 85 | U10: N/A | V10: 5 | W10: 15 | X10: 7.62mm NATO | Y10: {=INDEX(Caliber!B13:'Caliber'!C23,MATCH(INDIRECT(ADDRESS(ROW(),COLUMN()-1)),Caliber!B13:'Caliber'!B23,0),2)} -> 45 | Z10: {=INDEX(Caliber!C13:'Caliber'!D23,MATCH(INDIRECT(ADDRESS(ROW(),COLUMN()-2)),Caliber!B13:'Caliber'!B23,0),2)} -> 0.6 | AA10: [50,100]
A11: AUG HBAR | B11: 36 | C11: 1x3 | D11: 63000 | E11: TRUE | F11: TRUE | G11: N/A | H11: 145 | I11: N/A | J11: 60 | K11: 70 | L11: N/A | M11: 65 | N11: 40 | O11: N/A | P11: 40 | Q11: 20 | R11: 200 | S11: 5 | T11: 50 | U11: N/A | V11: 5 | W11: 15 | X11: 5.56mm | Y11: {=INDEX(Caliber!B13:'Caliber'!C23,MATCH(INDIRECT(ADDRESS(ROW(),COLUMN()-1)),Caliber!B13:'Caliber'!B23,0),2)} -> 37 | Z11: {=INDEX(Caliber!C14:'Caliber'!D24,MATCH(INDIRECT(ADDRESS(ROW(),COLUMN()-2)),Caliber!B14:'Caliber'!B24,0),2)} -> 0.4 | AA11: [30]
A12: MG36 | B12: 39 | C12: 1x3 | D12: 80000 | E12: TRUE | F12: TRUE | G12: N/A | H12: 145 | I12: N/A | J12: 35 | K12: 60 | L12: N/A | M12: 40 | N12: 20 | O12: N/A | P12: 30 | Q12: 15 | R12: 200 | S12: 5 | T12: 85 | U12: N/A | V12: 5 | W12: 15 | X12: 5.56mm | Y12: {=INDEX(Caliber!B13:'Caliber'!C23,MATCH(INDIRECT(ADDRESS(ROW(),COLUMN()-1)),Caliber!B13:'Caliber'!B23,0),2)} -> 37 | Z12: {=INDEX(Caliber!C14:'Caliber'!D24,MATCH(INDIRECT(ADDRESS(ROW(),COLUMN()-2)),Caliber!B14:'Caliber'!B24,0),2)} -> 0.4 | AA12: [30,100]
A13: C7A1 LSW | B13: 30 | C13: 1x3 | D13: N/A | E13: TRUE | F13: TRUE | G13: N/A | H13: 145 | I13: N/A | J13: 45 | K13: 65 | L13: N/A | M13: 45 | N13: 25 | O13: N/A | P13: 25 | Q13: 17 | R13: 200 | S13: 5 | T13: 85 | U13: N/A | V13: 5 | W13: 15 | X13: 5.56mm | Y13: {=INDEX(Caliber!B13:'Caliber'!C23,MATCH(INDIRECT(ADDRESS(ROW(),COLUMN()-1)),Caliber!B13:'Caliber'!B23,0),2)} -> 37 | Z13: {=INDEX(Caliber!C14:'Caliber'!D24,MATCH(INDIRECT(ADDRESS(ROW(),COLUMN()-2)),Caliber!B14:'Caliber'!B24,0),2)} -> 0.4 | AA13: [30,100]
A14: Ultimax 100 | B14: 48 | C14: 2x3 | D14: 57000 | E14: TRUE | F14: TRUE | G14: N/A | H14: 145 | I14: N/A | J14: 55 | K14: 60 | L14: N/A | M14: 63 | N14: 35 | O14: N/A | P14: 30 | Q14: 20 | R14: 200 | S14: 5 | T14: 85 | U14: N/A | V14: 5 | W14: 15 | X14: 5.56mm | Y14: {=INDEX(Caliber!B13:'Caliber'!C23,MATCH(INDIRECT(ADDRESS(ROW(),COLUMN()-1)),Caliber!B13:'Caliber'!B23,0),2)} -> 37 | Z14: {=INDEX(Caliber!C14:'Caliber'!D24,MATCH(INDIRECT(ADDRESS(ROW(),COLUMN()-2)),Caliber!B14:'Caliber'!B24,0),2)} -> 0.4 | AA14: [30,100]
